Traceback (most recent call last):
  File "/Users/murakaminaoki/git/atwiki/atwiki.py", line 33, in <module>
    driver.find_element_by_link_text("\u30ed\u30b0\u30a4\u30f3").click()
  File "/Users/murakaminaoki/anaconda3/lib/python3.6/site-packages/selenium/webdriver/remote/webdriver.py", line 421, in find_element_by_link_text
    return self.find_element(by=By.LINK_TEXT, value=link_text)
  File "/Users/murakaminaoki/anaconda3/lib/python3.6/site-packages/selenium/webdriver/remote/webdriver.py", line 957, in find_element
    'value': value})['value']
  File "/Users/murakaminaoki/anaconda3/lib/python3.6/site-packages/selenium/webdriver/remote/webdriver.py", line 314, in execute
    self.error_handler.check_response(response)
  File "/Users/murakaminaoki/anaconda3/lib/python3.6/site-packages/selenium/webdriver/remote/errorhandler.py", line 242, in check_response
    raise exception_class(message, screen, stacktrace)
selenium.common.exceptions.NoSuchElementException: Message: no such element: Unable to locate element: {"method":"link text","selector":"\u30ed\u30b0\u30a4\u30f3"}
  (Session info: headless chrome=67.0.3396.87)
  (Driver info: chromedriver=2.40.565386 (45a059dc425e08165f9a10324bd1380cc13ca363),platform=Mac OS X 10.13.5 x86_64)


During handling of the above exception, another exception occurred:

Traceback (most recent call last):
  File "/Users/murakaminaoki/git/atwiki/atwiki.py", line 42, in <module>
    print("\u4f8b\u5916\u304c\u767a\u751f\u3057\u307e\u3057\u305f\uff08\u30cd\u30c3\u30c8\u30ef\u30fc\u30af\u306b\u7e4b\u304c\u3063\u3066\u3044\u308b\u304b\u3054\u78ba\u8a8d\u304f\u3060\u3055\u3044")
UnicodeEncodeError: 'ascii' codec can't encode characters in position 0-30: ordinal not in range(128)
Traceback (most recent call last):
  File "/Users/murakaminaoki/git/atwiki/atwiki.py", line 33, in <module>
    driver.find_element_by_link_text("\u30ed\u30b0\u30a4\u30f3").click()
  File "/Users/murakaminaoki/anaconda3/lib/python3.6/site-packages/selenium/webdriver/remote/webdriver.py", line 421, in find_element_by_link_text
    return self.find_element(by=By.LINK_TEXT, value=link_text)
  File "/Users/murakaminaoki/anaconda3/lib/python3.6/site-packages/selenium/webdriver/remote/webdriver.py", line 957, in find_element
    'value': value})['value']
  File "/Users/murakaminaoki/anaconda3/lib/python3.6/site-packages/selenium/webdriver/remote/webdriver.py", line 314, in execute
    self.error_handler.check_response(response)
  File "/Users/murakaminaoki/anaconda3/lib/python3.6/site-packages/selenium/webdriver/remote/errorhandler.py", line 242, in check_response
    raise exception_class(message, screen, stacktrace)
selenium.common.exceptions.NoSuchElementException: Message: no such element: Unable to locate element: {"method":"link text","selector":"\u30ed\u30b0\u30a4\u30f3"}
  (Session info: headless chrome=67.0.3396.87)
  (Driver info: chromedriver=2.40.565386 (45a059dc425e08165f9a10324bd1380cc13ca363),platform=Mac OS X 10.13.5 x86_64)


During handling of the above exception, another exception occurred:

Traceback (most recent call last):
  File "/Users/murakaminaoki/git/atwiki/atwiki.py", line 42, in <module>
    print("\u4f8b\u5916\u304c\u767a\u751f\u3057\u307e\u3057\u305f\uff08\u30cd\u30c3\u30c8\u30ef\u30fc\u30af\u306b\u7e4b\u304c\u3063\u3066\u3044\u308b\u304b\u3054\u78ba\u8a8d\u304f\u3060\u3055\u3044")
UnicodeEncodeError: 'ascii' codec can't encode characters in position 0-30: ordinal not in range(128)
Traceback (most recent call last):
  File "/Users/murakaminaoki/git/atwiki/atwiki.py", line 33, in <module>
    driver.find_element_by_link_text("\u30ed\u30b0\u30a4\u30f3").click()
  File "/Users/murakaminaoki/anaconda3/lib/python3.6/site-packages/selenium/webdriver/remote/webdriver.py", line 421, in find_element_by_link_text
    return self.find_element(by=By.LINK_TEXT, value=link_text)
  File "/Users/murakaminaoki/anaconda3/lib/python3.6/site-packages/selenium/webdriver/remote/webdriver.py", line 957, in find_element
    'value': value})['value']
  File "/Users/murakaminaoki/anaconda3/lib/python3.6/site-packages/selenium/webdriver/remote/webdriver.py", line 314, in execute
    self.error_handler.check_response(response)
  File "/Users/murakaminaoki/anaconda3/lib/python3.6/site-packages/selenium/webdriver/remote/errorhandler.py", line 242, in check_response
    raise exception_class(message, screen, stacktrace)
selenium.common.exceptions.NoSuchElementException: Message: no such element: Unable to locate element: {"method":"link text","selector":"\u30ed\u30b0\u30a4\u30f3"}
  (Session info: headless chrome=67.0.3396.87)
  (Driver info: chromedriver=2.40.565386 (45a059dc425e08165f9a10324bd1380cc13ca363),platform=Mac OS X 10.13.5 x86_64)


During handling of the above exception, another exception occurred:

Traceback (most recent call last):
  File "/Users/murakaminaoki/git/atwiki/atwiki.py", line 42, in <module>
    print("\u4f8b\u5916\u304c\u767a\u751f\u3057\u307e\u3057\u305f\uff08\u30cd\u30c3\u30c8\u30ef\u30fc\u30af\u306b\u7e4b\u304c\u3063\u3066\u3044\u308b\u304b\u3054\u78ba\u8a8d\u304f\u3060\u3055\u3044")
UnicodeEncodeError: 'ascii' codec can't encode characters in position 0-30: ordinal not in range(128)
Traceback (most recent call last):
  File "/Users/murakaminaoki/git/atwiki/atwiki.py", line 31, in <module>
    driver.find_element_by_link_text("\u30ed\u30b0\u30a4\u30f3").click()
  File "/Users/murakaminaoki/anaconda3/lib/python3.6/site-packages/selenium/webdriver/remote/webdriver.py", line 421, in find_element_by_link_text
    return self.find_element(by=By.LINK_TEXT, value=link_text)
  File "/Users/murakaminaoki/anaconda3/lib/python3.6/site-packages/selenium/webdriver/remote/webdriver.py", line 957, in find_element
    'value': value})['value']
  File "/Users/murakaminaoki/anaconda3/lib/python3.6/site-packages/selenium/webdriver/remote/webdriver.py", line 314, in execute
    self.error_handler.check_response(response)
  File "/Users/murakaminaoki/anaconda3/lib/python3.6/site-packages/selenium/webdriver/remote/errorhandler.py", line 242, in check_response
    raise exception_class(message, screen, stacktrace)
selenium.common.exceptions.NoSuchElementException: Message: no such element: Unable to locate element: {"method":"link text","selector":"\u30ed\u30b0\u30a4\u30f3"}
  (Session info: headless chrome=67.0.3396.87)
  (Driver info: chromedriver=2.40.565386 (45a059dc425e08165f9a10324bd1380cc13ca363),platform=Mac OS X 10.13.5 x86_64)


During handling of the above exception, another exception occurred:

Traceback (most recent call last):
  File "/Users/murakaminaoki/git/atwiki/atwiki.py", line 40, in <module>
    print("\u4f8b\u5916\u304c\u767a\u751f\u3057\u307e\u3057\u305f\uff08\u30cd\u30c3\u30c8\u30ef\u30fc\u30af\u306b\u7e4b\u304c\u3063\u3066\u3044\u308b\u304b\u3054\u78ba\u8a8d\u304f\u3060\u3055\u3044\uff09")
UnicodeEncodeError: 'ascii' codec can't encode characters in position 0-31: ordinal not in range(128)
Traceback (most recent call last):
  File "/Users/murakaminaoki/git/atwiki/atwiki.py", line 31, in <module>
    driver.find_element_by_link_text("\u30ed\u30b0\u30a4\u30f3").click()
  File "/Users/murakaminaoki/anaconda3/lib/python3.6/site-packages/selenium/webdriver/remote/webdriver.py", line 421, in find_element_by_link_text
    return self.find_element(by=By.LINK_TEXT, value=link_text)
  File "/Users/murakaminaoki/anaconda3/lib/python3.6/site-packages/selenium/webdriver/remote/webdriver.py", line 957, in find_element
    'value': value})['value']
  File "/Users/murakaminaoki/anaconda3/lib/python3.6/site-packages/selenium/webdriver/remote/webdriver.py", line 314, in execute
    self.error_handler.check_response(response)
  File "/Users/murakaminaoki/anaconda3/lib/python3.6/site-packages/selenium/webdriver/remote/errorhandler.py", line 242, in check_response
    raise exception_class(message, screen, stacktrace)
selenium.common.exceptions.NoSuchElementException: Message: no such element: Unable to locate element: {"method":"link text","selector":"\u30ed\u30b0\u30a4\u30f3"}
  (Session info: headless chrome=67.0.3396.87)
  (Driver info: chromedriver=2.40.565386 (45a059dc425e08165f9a10324bd1380cc13ca363),platform=Mac OS X 10.13.5 x86_64)


During handling of the above exception, another exception occurred:

Traceback (most recent call last):
  File "/Users/murakaminaoki/git/atwiki/atwiki.py", line 40, in <module>
    print("\u4f8b\u5916\u304c\u767a\u751f\u3057\u307e\u3057\u305f\uff08\u30cd\u30c3\u30c8\u30ef\u30fc\u30af\u306b\u7e4b\u304c\u3063\u3066\u3044\u308b\u304b\u3054\u78ba\u8a8d\u304f\u3060\u3055\u3044\uff09")
UnicodeEncodeError: 'ascii' codec can't encode characters in position 0-31: ordinal not in range(128)
Traceback (most recent call last):
  File "/Users/murakaminaoki/git/atwiki/atwiki.py", line 31, in <module>
    driver.find_element_by_link_text("\u30ed\u30b0\u30a4\u30f3").click()
  File "/Users/murakaminaoki/anaconda3/lib/python3.6/site-packages/selenium/webdriver/remote/webdriver.py", line 421, in find_element_by_link_text
    return self.find_element(by=By.LINK_TEXT, value=link_text)
  File "/Users/murakaminaoki/anaconda3/lib/python3.6/site-packages/selenium/webdriver/remote/webdriver.py", line 957, in find_element
    'value': value})['value']
  File "/Users/murakaminaoki/anaconda3/lib/python3.6/site-packages/selenium/webdriver/remote/webdriver.py", line 314, in execute
    self.error_handler.check_response(response)
  File "/Users/murakaminaoki/anaconda3/lib/python3.6/site-packages/selenium/webdriver/remote/errorhandler.py", line 242, in check_response
    raise exception_class(message, screen, stacktrace)
selenium.common.exceptions.NoSuchElementException: Message: no such element: Unable to locate element: {"method":"link text","selector":"\u30ed\u30b0\u30a4\u30f3"}
  (Session info: headless chrome=67.0.3396.87)
  (Driver info: chromedriver=2.40.565386 (45a059dc425e08165f9a10324bd1380cc13ca363),platform=Mac OS X 10.13.5 x86_64)


During handling of the above exception, another exception occurred:

Traceback (most recent call last):
  File "/Users/murakaminaoki/git/atwiki/atwiki.py", line 40, in <module>
    print("\u4f8b\u5916\u304c\u767a\u751f\u3057\u307e\u3057\u305f\uff08\u30cd\u30c3\u30c8\u30ef\u30fc\u30af\u306b\u7e4b\u304c\u3063\u3066\u3044\u308b\u304b\u3054\u78ba\u8a8d\u304f\u3060\u3055\u3044\uff09")
UnicodeEncodeError: 'ascii' codec can't encode characters in position 0-31: ordinal not in range(128)
Traceback (most recent call last):
  File "/Users/murakaminaoki/git/atwiki/atwiki.py", line 31, in <module>
    driver.find_element_by_link_text("\u30ed\u30b0\u30a4\u30f3").click()
  File "/Users/murakaminaoki/anaconda3/lib/python3.6/site-packages/selenium/webdriver/remote/webdriver.py", line 421, in find_element_by_link_text
    return self.find_element(by=By.LINK_TEXT, value=link_text)
  File "/Users/murakaminaoki/anaconda3/lib/python3.6/site-packages/selenium/webdriver/remote/webdriver.py", line 957, in find_element
    'value': value})['value']
  File "/Users/murakaminaoki/anaconda3/lib/python3.6/site-packages/selenium/webdriver/remote/webdriver.py", line 314, in execute
    self.error_handler.check_response(response)
  File "/Users/murakaminaoki/anaconda3/lib/python3.6/site-packages/selenium/webdriver/remote/errorhandler.py", line 242, in check_response
    raise exception_class(message, screen, stacktrace)
selenium.common.exceptions.NoSuchElementException: Message: no such element: Unable to locate element: {"method":"link text","selector":"\u30ed\u30b0\u30a4\u30f3"}
  (Session info: headless chrome=67.0.3396.87)
  (Driver info: chromedriver=2.40.565386 (45a059dc425e08165f9a10324bd1380cc13ca363),platform=Mac OS X 10.13.5 x86_64)


During handling of the above exception, another exception occurred:

Traceback (most recent call last):
  File "/Users/murakaminaoki/git/atwiki/atwiki.py", line 40, in <module>
    print("\u4f8b\u5916\u304c\u767a\u751f\u3057\u307e\u3057\u305f\uff08\u30cd\u30c3\u30c8\u30ef\u30fc\u30af\u306b\u7e4b\u304c\u3063\u3066\u3044\u308b\u304b\u3054\u78ba\u8a8d\u304f\u3060\u3055\u3044\uff09")
UnicodeEncodeError: 'ascii' codec can't encode characters in position 0-31: ordinal not in range(128)
Traceback (most recent call last):
  File "/Users/murakaminaoki/git/atwiki/atwiki.py", line 31, in <module>
    driver.find_element_by_link_text("\u30ed\u30b0\u30a4\u30f3").click()
  File "/Users/murakaminaoki/anaconda3/lib/python3.6/site-packages/selenium/webdriver/remote/webdriver.py", line 421, in find_element_by_link_text
    return self.find_element(by=By.LINK_TEXT, value=link_text)
  File "/Users/murakaminaoki/anaconda3/lib/python3.6/site-packages/selenium/webdriver/remote/webdriver.py", line 957, in find_element
    'value': value})['value']
  File "/Users/murakaminaoki/anaconda3/lib/python3.6/site-packages/selenium/webdriver/remote/webdriver.py", line 314, in execute
    self.error_handler.check_response(response)
  File "/Users/murakaminaoki/anaconda3/lib/python3.6/site-packages/selenium/webdriver/remote/errorhandler.py", line 242, in check_response
    raise exception_class(message, screen, stacktrace)
selenium.common.exceptions.NoSuchElementException: Message: no such element: Unable to locate element: {"method":"link text","selector":"\u30ed\u30b0\u30a4\u30f3"}
  (Session info: headless chrome=67.0.3396.87)
  (Driver info: chromedriver=2.40.565386 (45a059dc425e08165f9a10324bd1380cc13ca363),platform=Mac OS X 10.13.5 x86_64)


During handling of the above exception, another exception occurred:

Traceback (most recent call last):
  File "/Users/murakaminaoki/git/atwiki/atwiki.py", line 40, in <module>
    print("\u4f8b\u5916\u304c\u767a\u751f\u3057\u307e\u3057\u305f\uff08\u30cd\u30c3\u30c8\u30ef\u30fc\u30af\u306b\u7e4b\u304c\u3063\u3066\u3044\u308b\u304b\u3054\u78ba\u8a8d\u304f\u3060\u3055\u3044\uff09")
UnicodeEncodeError: 'ascii' codec can't encode characters in position 0-31: ordinal not in range(128)
Traceback (most recent call last):
  File "/Users/murakaminaoki/git/atwiki/atwiki.py", line 31, in <module>
    driver.find_element_by_link_text("\u30ed\u30b0\u30a4\u30f3").click()
  File "/Users/murakaminaoki/anaconda3/lib/python3.6/site-packages/selenium/webdriver/remote/webdriver.py", line 421, in find_element_by_link_text
    return self.find_element(by=By.LINK_TEXT, value=link_text)
  File "/Users/murakaminaoki/anaconda3/lib/python3.6/site-packages/selenium/webdriver/remote/webdriver.py", line 957, in find_element
    'value': value})['value']
  File "/Users/murakaminaoki/anaconda3/lib/python3.6/site-packages/selenium/webdriver/remote/webdriver.py", line 314, in execute
    self.error_handler.check_response(response)
  File "/Users/murakaminaoki/anaconda3/lib/python3.6/site-packages/selenium/webdriver/remote/errorhandler.py", line 242, in check_response
    raise exception_class(message, screen, stacktrace)
selenium.common.exceptions.NoSuchElementException: Message: no such element: Unable to locate element: {"method":"link text","selector":"\u30ed\u30b0\u30a4\u30f3"}
  (Session info: headless chrome=67.0.3396.87)
  (Driver info: chromedriver=2.40.565386 (45a059dc425e08165f9a10324bd1380cc13ca363),platform=Mac OS X 10.13.5 x86_64)


During handling of the above exception, another exception occurred:

Traceback (most recent call last):
  File "/Users/murakaminaoki/git/atwiki/atwiki.py", line 40, in <module>
    print("\u4f8b\u5916\u304c\u767a\u751f\u3057\u307e\u3057\u305f\uff08\u30cd\u30c3\u30c8\u30ef\u30fc\u30af\u306b\u7e4b\u304c\u3063\u3066\u3044\u308b\u304b\u3054\u78ba\u8a8d\u304f\u3060\u3055\u3044\uff09")
UnicodeEncodeError: 'ascii' codec can't encode characters in position 0-31: ordinal not in range(128)
Traceback (most recent call last):
  File "/Users/murakaminaoki/git/atwiki/atwiki.py", line 31, in <module>
    driver.find_element_by_link_text("\u30ed\u30b0\u30a4\u30f3").click()
  File "/Users/murakaminaoki/anaconda3/lib/python3.6/site-packages/selenium/webdriver/remote/webdriver.py", line 421, in find_element_by_link_text
    return self.find_element(by=By.LINK_TEXT, value=link_text)
  File "/Users/murakaminaoki/anaconda3/lib/python3.6/site-packages/selenium/webdriver/remote/webdriver.py", line 957, in find_element
    'value': value})['value']
  File "/Users/murakaminaoki/anaconda3/lib/python3.6/site-packages/selenium/webdriver/remote/webdriver.py", line 314, in execute
    self.error_handler.check_response(response)
  File "/Users/murakaminaoki/anaconda3/lib/python3.6/site-packages/selenium/webdriver/remote/errorhandler.py", line 242, in check_response
    raise exception_class(message, screen, stacktrace)
selenium.common.exceptions.NoSuchElementException: Message: no such element: Unable to locate element: {"method":"link text","selector":"\u30ed\u30b0\u30a4\u30f3"}
  (Session info: headless chrome=67.0.3396.87)
  (Driver info: chromedriver=2.40.565386 (45a059dc425e08165f9a10324bd1380cc13ca363),platform=Mac OS X 10.13.5 x86_64)


During handling of the above exception, another exception occurred:

Traceback (most recent call last):
  File "/Users/murakaminaoki/git/atwiki/atwiki.py", line 40, in <module>
    print("\u4f8b\u5916\u304c\u767a\u751f\u3057\u307e\u3057\u305f\uff08\u30cd\u30c3\u30c8\u30ef\u30fc\u30af\u306b\u7e4b\u304c\u3063\u3066\u3044\u308b\u304b\u3054\u78ba\u8a8d\u304f\u3060\u3055\u3044\uff09")
UnicodeEncodeError: 'ascii' codec can't encode characters in position 0-31: ordinal not in range(128)
Traceback (most recent call last):
  File "/Users/murakaminaoki/git/atwiki/atwiki.py", line 31, in <module>
    driver.find_element_by_link_text("\u30ed\u30b0\u30a4\u30f3").click()
  File "/Users/murakaminaoki/anaconda3/lib/python3.6/site-packages/selenium/webdriver/remote/webdriver.py", line 421, in find_element_by_link_text
    return self.find_element(by=By.LINK_TEXT, value=link_text)
  File "/Users/murakaminaoki/anaconda3/lib/python3.6/site-packages/selenium/webdriver/remote/webdriver.py", line 957, in find_element
    'value': value})['value']
  File "/Users/murakaminaoki/anaconda3/lib/python3.6/site-packages/selenium/webdriver/remote/webdriver.py", line 314, in execute
    self.error_handler.check_response(response)
  File "/Users/murakaminaoki/anaconda3/lib/python3.6/site-packages/selenium/webdriver/remote/errorhandler.py", line 242, in check_response
    raise exception_class(message, screen, stacktrace)
selenium.common.exceptions.NoSuchElementException: Message: no such element: Unable to locate element: {"method":"link text","selector":"\u30ed\u30b0\u30a4\u30f3"}
  (Session info: headless chrome=67.0.3396.87)
  (Driver info: chromedriver=2.40.565386 (45a059dc425e08165f9a10324bd1380cc13ca363),platform=Mac OS X 10.13.5 x86_64)


During handling of the above exception, another exception occurred:

Traceback (most recent call last):
  File "/Users/murakaminaoki/git/atwiki/atwiki.py", line 40, in <module>
    print("\u4f8b\u5916\u304c\u767a\u751f\u3057\u307e\u3057\u305f\uff08\u30cd\u30c3\u30c8\u30ef\u30fc\u30af\u306b\u7e4b\u304c\u3063\u3066\u3044\u308b\u304b\u3054\u78ba\u8a8d\u304f\u3060\u3055\u3044\uff09")
UnicodeEncodeError: 'ascii' codec can't encode characters in position 0-31: ordinal not in range(128)
Traceback (most recent call last):
  File "/Users/murakaminaoki/git/atwiki/atwiki.py", line 31, in <module>
    driver.find_element_by_link_text("\u30ed\u30b0\u30a4\u30f3").click()
  File "/Users/murakaminaoki/anaconda3/lib/python3.6/site-packages/selenium/webdriver/remote/webdriver.py", line 421, in find_element_by_link_text
    return self.find_element(by=By.LINK_TEXT, value=link_text)
  File "/Users/murakaminaoki/anaconda3/lib/python3.6/site-packages/selenium/webdriver/remote/webdriver.py", line 957, in find_element
    'value': value})['value']
  File "/Users/murakaminaoki/anaconda3/lib/python3.6/site-packages/selenium/webdriver/remote/webdriver.py", line 314, in execute
    self.error_handler.check_response(response)
  File "/Users/murakaminaoki/anaconda3/lib/python3.6/site-packages/selenium/webdriver/remote/errorhandler.py", line 242, in check_response
    raise exception_class(message, screen, stacktrace)
selenium.common.exceptions.NoSuchElementException: Message: no such element: Unable to locate element: {"method":"link text","selector":"\u30ed\u30b0\u30a4\u30f3"}
  (Session info: headless chrome=67.0.3396.87)
  (Driver info: chromedriver=2.40.565386 (45a059dc425e08165f9a10324bd1380cc13ca363),platform=Mac OS X 10.13.5 x86_64)


During handling of the above exception, another exception occurred:

Traceback (most recent call last):
  File "/Users/murakaminaoki/git/atwiki/atwiki.py", line 40, in <module>
    print("\u4f8b\u5916\u304c\u767a\u751f\u3057\u307e\u3057\u305f\uff08\u30cd\u30c3\u30c8\u30ef\u30fc\u30af\u306b\u7e4b\u304c\u3063\u3066\u3044\u308b\u304b\u3054\u78ba\u8a8d\u304f\u3060\u3055\u3044\uff09")
UnicodeEncodeError: 'ascii' codec can't encode characters in position 0-31: ordinal not in range(128)
Traceback (most recent call last):
  File "/Users/murakaminaoki/git/atwiki/atwiki.py", line 31, in <module>
    driver.find_element_by_link_text("\u30ed\u30b0\u30a4\u30f3").click()
  File "/Users/murakaminaoki/anaconda3/lib/python3.6/site-packages/selenium/webdriver/remote/webdriver.py", line 421, in find_element_by_link_text
    return self.find_element(by=By.LINK_TEXT, value=link_text)
  File "/Users/murakaminaoki/anaconda3/lib/python3.6/site-packages/selenium/webdriver/remote/webdriver.py", line 957, in find_element
    'value': value})['value']
  File "/Users/murakaminaoki/anaconda3/lib/python3.6/site-packages/selenium/webdriver/remote/webdriver.py", line 314, in execute
    self.error_handler.check_response(response)
  File "/Users/murakaminaoki/anaconda3/lib/python3.6/site-packages/selenium/webdriver/remote/errorhandler.py", line 242, in check_response
    raise exception_class(message, screen, stacktrace)
selenium.common.exceptions.NoSuchElementException: Message: no such element: Unable to locate element: {"method":"link text","selector":"\u30ed\u30b0\u30a4\u30f3"}
  (Session info: headless chrome=67.0.3396.87)
  (Driver info: chromedriver=2.40.565386 (45a059dc425e08165f9a10324bd1380cc13ca363),platform=Mac OS X 10.13.5 x86_64)


During handling of the above exception, another exception occurred:

Traceback (most recent call last):
  File "/Users/murakaminaoki/git/atwiki/atwiki.py", line 40, in <module>
    print("\u4f8b\u5916\u304c\u767a\u751f\u3057\u307e\u3057\u305f\uff08\u30cd\u30c3\u30c8\u30ef\u30fc\u30af\u306b\u7e4b\u304c\u3063\u3066\u3044\u308b\u304b\u3054\u78ba\u8a8d\u304f\u3060\u3055\u3044\uff09")
UnicodeEncodeError: 'ascii' codec can't encode characters in position 0-31: ordinal not in range(128)
Traceback (most recent call last):
  File "/Users/murakaminaoki/git/atwiki/atwiki.py", line 31, in <module>
    driver.find_element_by_link_text("\u30ed\u30b0\u30a4\u30f3").click()
  File "/Users/murakaminaoki/anaconda3/lib/python3.6/site-packages/selenium/webdriver/remote/webdriver.py", line 421, in find_element_by_link_text
    return self.find_element(by=By.LINK_TEXT, value=link_text)
  File "/Users/murakaminaoki/anaconda3/lib/python3.6/site-packages/selenium/webdriver/remote/webdriver.py", line 957, in find_element
    'value': value})['value']
  File "/Users/murakaminaoki/anaconda3/lib/python3.6/site-packages/selenium/webdriver/remote/webdriver.py", line 314, in execute
    self.error_handler.check_response(response)
  File "/Users/murakaminaoki/anaconda3/lib/python3.6/site-packages/selenium/webdriver/remote/errorhandler.py", line 242, in check_response
    raise exception_class(message, screen, stacktrace)
selenium.common.exceptions.NoSuchElementException: Message: no such element: Unable to locate element: {"method":"link text","selector":"\u30ed\u30b0\u30a4\u30f3"}
  (Session info: headless chrome=67.0.3396.87)
  (Driver info: chromedriver=2.40.565386 (45a059dc425e08165f9a10324bd1380cc13ca363),platform=Mac OS X 10.13.5 x86_64)


During handling of the above exception, another exception occurred:

Traceback (most recent call last):
  File "/Users/murakaminaoki/git/atwiki/atwiki.py", line 40, in <module>
    print("\u4f8b\u5916\u304c\u767a\u751f\u3057\u307e\u3057\u305f\uff08\u30cd\u30c3\u30c8\u30ef\u30fc\u30af\u306b\u7e4b\u304c\u3063\u3066\u3044\u308b\u304b\u3054\u78ba\u8a8d\u304f\u3060\u3055\u3044\uff09")
UnicodeEncodeError: 'ascii' codec can't encode characters in position 0-31: ordinal not in range(128)
Traceback (most recent call last):
  File "/Users/murakaminaoki/git/atwiki/atwiki.py", line 31, in <module>
    driver.find_element_by_link_text("\u30ed\u30b0\u30a4\u30f3").click()
  File "/Users/murakaminaoki/anaconda3/lib/python3.6/site-packages/selenium/webdriver/remote/webdriver.py", line 421, in find_element_by_link_text
    return self.find_element(by=By.LINK_TEXT, value=link_text)
  File "/Users/murakaminaoki/anaconda3/lib/python3.6/site-packages/selenium/webdriver/remote/webdriver.py", line 957, in find_element
    'value': value})['value']
  File "/Users/murakaminaoki/anaconda3/lib/python3.6/site-packages/selenium/webdriver/remote/webdriver.py", line 314, in execute
    self.error_handler.check_response(response)
  File "/Users/murakaminaoki/anaconda3/lib/python3.6/site-packages/selenium/webdriver/remote/errorhandler.py", line 242, in check_response
    raise exception_class(message, screen, stacktrace)
selenium.common.exceptions.NoSuchElementException: Message: no such element: Unable to locate element: {"method":"link text","selector":"\u30ed\u30b0\u30a4\u30f3"}
  (Session info: headless chrome=67.0.3396.99)
  (Driver info: chromedriver=2.40.565386 (45a059dc425e08165f9a10324bd1380cc13ca363),platform=Mac OS X 10.13.5 x86_64)


During handling of the above exception, another exception occurred:

Traceback (most recent call last):
  File "/Users/murakaminaoki/git/atwiki/atwiki.py", line 40, in <module>
    print("\u4f8b\u5916\u304c\u767a\u751f\u3057\u307e\u3057\u305f\uff08\u30cd\u30c3\u30c8\u30ef\u30fc\u30af\u306b\u7e4b\u304c\u3063\u3066\u3044\u308b\u304b\u3054\u78ba\u8a8d\u304f\u3060\u3055\u3044\uff09")
UnicodeEncodeError: 'ascii' codec can't encode characters in position 0-31: ordinal not in range(128)
Traceback (most recent call last):
  File "/Users/murakaminaoki/git/atwiki/atwiki.py", line 31, in <module>
    driver.find_element_by_link_text("\u30ed\u30b0\u30a4\u30f3").click()
  File "/Users/murakaminaoki/anaconda3/lib/python3.6/site-packages/selenium/webdriver/remote/webdriver.py", line 421, in find_element_by_link_text
    return self.find_element(by=By.LINK_TEXT, value=link_text)
  File "/Users/murakaminaoki/anaconda3/lib/python3.6/site-packages/selenium/webdriver/remote/webdriver.py", line 957, in find_element
    'value': value})['value']
  File "/Users/murakaminaoki/anaconda3/lib/python3.6/site-packages/selenium/webdriver/remote/webdriver.py", line 314, in execute
    self.error_handler.check_response(response)
  File "/Users/murakaminaoki/anaconda3/lib/python3.6/site-packages/selenium/webdriver/remote/errorhandler.py", line 242, in check_response
    raise exception_class(message, screen, stacktrace)
selenium.common.exceptions.NoSuchElementException: Message: no such element: Unable to locate element: {"method":"link text","selector":"\u30ed\u30b0\u30a4\u30f3"}
  (Session info: headless chrome=67.0.3396.99)
  (Driver info: chromedriver=2.40.565386 (45a059dc425e08165f9a10324bd1380cc13ca363),platform=Mac OS X 10.13.5 x86_64)


During handling of the above exception, another exception occurred:

Traceback (most recent call last):
  File "/Users/murakaminaoki/git/atwiki/atwiki.py", line 40, in <module>
    print("\u4f8b\u5916\u304c\u767a\u751f\u3057\u307e\u3057\u305f\uff08\u30cd\u30c3\u30c8\u30ef\u30fc\u30af\u306b\u7e4b\u304c\u3063\u3066\u3044\u308b\u304b\u3054\u78ba\u8a8d\u304f\u3060\u3055\u3044\uff09")
UnicodeEncodeError: 'ascii' codec can't encode characters in position 0-31: ordinal not in range(128)
Traceback (most recent call last):
  File "/Users/murakaminaoki/git/atwiki/atwiki.py", line 38, in <module>
    recent = driver.find_element_by_class_name("atwiki_plugin_recent_25a1b13fb87d062d43bd6fe2d4a85a7d").text
  File "/Users/murakaminaoki/anaconda3/lib/python3.6/site-packages/selenium/webdriver/remote/webdriver.py", line 557, in find_element_by_class_name
    return self.find_element(by=By.CLASS_NAME, value=name)
  File "/Users/murakaminaoki/anaconda3/lib/python3.6/site-packages/selenium/webdriver/remote/webdriver.py", line 957, in find_element
    'value': value})['value']
  File "/Users/murakaminaoki/anaconda3/lib/python3.6/site-packages/selenium/webdriver/remote/webdriver.py", line 314, in execute
    self.error_handler.check_response(response)
  File "/Users/murakaminaoki/anaconda3/lib/python3.6/site-packages/selenium/webdriver/remote/errorhandler.py", line 242, in check_response
    raise exception_class(message, screen, stacktrace)
selenium.common.exceptions.NoSuchElementException: Message: no such element: Unable to locate element: {"method":"class name","selector":"atwiki_plugin_recent_25a1b13fb87d062d43bd6fe2d4a85a7d"}
  (Session info: headless chrome=67.0.3396.99)
  (Driver info: chromedriver=2.40.565386 (45a059dc425e08165f9a10324bd1380cc13ca363),platform=Mac OS X 10.13.5 x86_64)


During handling of the above exception, another exception occurred:

Traceback (most recent call last):
  File "/Users/murakaminaoki/git/atwiki/atwiki.py", line 40, in <module>
    print("\u4f8b\u5916\u304c\u767a\u751f\u3057\u307e\u3057\u305f\uff08\u30cd\u30c3\u30c8\u30ef\u30fc\u30af\u306b\u7e4b\u304c\u3063\u3066\u3044\u308b\u304b\u3054\u78ba\u8a8d\u304f\u3060\u3055\u3044\uff09")
UnicodeEncodeError: 'ascii' codec can't encode characters in position 0-31: ordinal not in range(128)
Traceback (most recent call last):
  File "/Users/murakaminaoki/git/atwiki/atwiki.py", line 32, in <module>
    driver.find_element_by_name("user").send_keys(user)
  File "/Users/murakaminaoki/anaconda3/lib/python3.6/site-packages/selenium/webdriver/remote/webdriver.py", line 489, in find_element_by_name
    return self.find_element(by=By.NAME, value=name)
  File "/Users/murakaminaoki/anaconda3/lib/python3.6/site-packages/selenium/webdriver/remote/webdriver.py", line 957, in find_element
    'value': value})['value']
  File "/Users/murakaminaoki/anaconda3/lib/python3.6/site-packages/selenium/webdriver/remote/webdriver.py", line 314, in execute
    self.error_handler.check_response(response)
  File "/Users/murakaminaoki/anaconda3/lib/python3.6/site-packages/selenium/webdriver/remote/errorhandler.py", line 242, in check_response
    raise exception_class(message, screen, stacktrace)
selenium.common.exceptions.NoSuchElementException: Message: no such element: Unable to locate element: {"method":"name","selector":"user"}
  (Session info: headless chrome=67.0.3396.99)
  (Driver info: chromedriver=2.40.565386 (45a059dc425e08165f9a10324bd1380cc13ca363),platform=Mac OS X 10.13.5 x86_64)


During handling of the above exception, another exception occurred:

Traceback (most recent call last):
  File "/Users/murakaminaoki/git/atwiki/atwiki.py", line 40, in <module>
    print("\u4f8b\u5916\u304c\u767a\u751f\u3057\u307e\u3057\u305f\uff08\u30cd\u30c3\u30c8\u30ef\u30fc\u30af\u306b\u7e4b\u304c\u3063\u3066\u3044\u308b\u304b\u3054\u78ba\u8a8d\u304f\u3060\u3055\u3044\uff09")
UnicodeEncodeError: 'ascii' codec can't encode characters in position 0-31: ordinal not in range(128)
Traceback (most recent call last):
  File "/Users/murakaminaoki/git/atwiki/atwiki.py", line 34, in <module>
    driver.find_element_by_name("login").click()
  File "/Users/murakaminaoki/anaconda3/lib/python3.6/site-packages/selenium/webdriver/remote/webdriver.py", line 489, in find_element_by_name
    return self.find_element(by=By.NAME, value=name)
  File "/Users/murakaminaoki/anaconda3/lib/python3.6/site-packages/selenium/webdriver/remote/webdriver.py", line 957, in find_element
    'value': value})['value']
  File "/Users/murakaminaoki/anaconda3/lib/python3.6/site-packages/selenium/webdriver/remote/webdriver.py", line 314, in execute
    self.error_handler.check_response(response)
  File "/Users/murakaminaoki/anaconda3/lib/python3.6/site-packages/selenium/webdriver/remote/errorhandler.py", line 242, in check_response
    raise exception_class(message, screen, stacktrace)
selenium.common.exceptions.NoSuchElementException: Message: no such element: Unable to locate element: {"method":"name","selector":"login"}
  (Session info: headless chrome=67.0.3396.99)
  (Driver info: chromedriver=2.40.565386 (45a059dc425e08165f9a10324bd1380cc13ca363),platform=Mac OS X 10.13.6 x86_64)


During handling of the above exception, another exception occurred:

Traceback (most recent call last):
  File "/Users/murakaminaoki/git/atwiki/atwiki.py", line 40, in <module>
    print("\u4f8b\u5916\u304c\u767a\u751f\u3057\u307e\u3057\u305f\uff08\u30cd\u30c3\u30c8\u30ef\u30fc\u30af\u306b\u7e4b\u304c\u3063\u3066\u3044\u308b\u304b\u3054\u78ba\u8a8d\u304f\u3060\u3055\u3044\uff09")
UnicodeEncodeError: 'ascii' codec can't encode characters in position 0-31: ordinal not in range(128)
Traceback (most recent call last):
  File "/Users/murakaminaoki/git/atwiki/atwiki.py", line 34, in <module>
    driver.find_element_by_name("login").click()
  File "/Users/murakaminaoki/anaconda3/lib/python3.6/site-packages/selenium/webdriver/remote/webdriver.py", line 489, in find_element_by_name
    return self.find_element(by=By.NAME, value=name)
  File "/Users/murakaminaoki/anaconda3/lib/python3.6/site-packages/selenium/webdriver/remote/webdriver.py", line 957, in find_element
    'value': value})['value']
  File "/Users/murakaminaoki/anaconda3/lib/python3.6/site-packages/selenium/webdriver/remote/webdriver.py", line 314, in execute
    self.error_handler.check_response(response)
  File "/Users/murakaminaoki/anaconda3/lib/python3.6/site-packages/selenium/webdriver/remote/errorhandler.py", line 242, in check_response
    raise exception_class(message, screen, stacktrace)
selenium.common.exceptions.NoSuchElementException: Message: no such element: Unable to locate element: {"method":"name","selector":"login"}
  (Session info: headless chrome=67.0.3396.99)
  (Driver info: chromedriver=2.40.565386 (45a059dc425e08165f9a10324bd1380cc13ca363),platform=Mac OS X 10.13.6 x86_64)


During handling of the above exception, another exception occurred:

Traceback (most recent call last):
  File "/Users/murakaminaoki/git/atwiki/atwiki.py", line 40, in <module>
    print("\u4f8b\u5916\u304c\u767a\u751f\u3057\u307e\u3057\u305f\uff08\u30cd\u30c3\u30c8\u30ef\u30fc\u30af\u306b\u7e4b\u304c\u3063\u3066\u3044\u308b\u304b\u3054\u78ba\u8a8d\u304f\u3060\u3055\u3044\uff09")
UnicodeEncodeError: 'ascii' codec can't encode characters in position 0-31: ordinal not in range(128)
Traceback (most recent call last):
  File "/Users/murakaminaoki/git/atwiki/atwiki.py", line 34, in <module>
    driver.find_element_by_name("login").click()
  File "/Users/murakaminaoki/anaconda3/lib/python3.6/site-packages/selenium/webdriver/remote/webdriver.py", line 489, in find_element_by_name
    return self.find_element(by=By.NAME, value=name)
  File "/Users/murakaminaoki/anaconda3/lib/python3.6/site-packages/selenium/webdriver/remote/webdriver.py", line 957, in find_element
    'value': value})['value']
  File "/Users/murakaminaoki/anaconda3/lib/python3.6/site-packages/selenium/webdriver/remote/webdriver.py", line 314, in execute
    self.error_handler.check_response(response)
  File "/Users/murakaminaoki/anaconda3/lib/python3.6/site-packages/selenium/webdriver/remote/errorhandler.py", line 242, in check_response
    raise exception_class(message, screen, stacktrace)
selenium.common.exceptions.NoSuchElementException: Message: no such element: Unable to locate element: {"method":"name","selector":"login"}
  (Session info: headless chrome=67.0.3396.99)
  (Driver info: chromedriver=2.40.565386 (45a059dc425e08165f9a10324bd1380cc13ca363),platform=Mac OS X 10.13.6 x86_64)


During handling of the above exception, another exception occurred:

Traceback (most recent call last):
  File "/Users/murakaminaoki/git/atwiki/atwiki.py", line 40, in <module>
    print("\u4f8b\u5916\u304c\u767a\u751f\u3057\u307e\u3057\u305f\uff08\u30cd\u30c3\u30c8\u30ef\u30fc\u30af\u306b\u7e4b\u304c\u3063\u3066\u3044\u308b\u304b\u3054\u78ba\u8a8d\u304f\u3060\u3055\u3044\uff09")
UnicodeEncodeError: 'ascii' codec can't encode characters in position 0-31: ordinal not in range(128)
Traceback (most recent call last):
  File "/Users/murakaminaoki/git/atwiki/atwiki.py", line 34, in <module>
    driver.find_element_by_name("login").click()
  File "/Users/murakaminaoki/anaconda3/lib/python3.6/site-packages/selenium/webdriver/remote/webdriver.py", line 489, in find_element_by_name
    return self.find_element(by=By.NAME, value=name)
  File "/Users/murakaminaoki/anaconda3/lib/python3.6/site-packages/selenium/webdriver/remote/webdriver.py", line 957, in find_element
    'value': value})['value']
  File "/Users/murakaminaoki/anaconda3/lib/python3.6/site-packages/selenium/webdriver/remote/webdriver.py", line 314, in execute
    self.error_handler.check_response(response)
  File "/Users/murakaminaoki/anaconda3/lib/python3.6/site-packages/selenium/webdriver/remote/errorhandler.py", line 242, in check_response
    raise exception_class(message, screen, stacktrace)
selenium.common.exceptions.NoSuchElementException: Message: no such element: Unable to locate element: {"method":"name","selector":"login"}
  (Session info: headless chrome=67.0.3396.99)
  (Driver info: chromedriver=2.40.565386 (45a059dc425e08165f9a10324bd1380cc13ca363),platform=Mac OS X 10.13.6 x86_64)


During handling of the above exception, another exception occurred:

Traceback (most recent call last):
  File "/Users/murakaminaoki/git/atwiki/atwiki.py", line 40, in <module>
    print("\u4f8b\u5916\u304c\u767a\u751f\u3057\u307e\u3057\u305f\uff08\u30cd\u30c3\u30c8\u30ef\u30fc\u30af\u306b\u7e4b\u304c\u3063\u3066\u3044\u308b\u304b\u3054\u78ba\u8a8d\u304f\u3060\u3055\u3044\uff09")
UnicodeEncodeError: 'ascii' codec can't encode characters in position 0-31: ordinal not in range(128)
Traceback (most recent call last):
  File "/Users/murakaminaoki/git/atwiki/atwiki.py", line 31, in <module>
    driver.find_element_by_link_text("\u30ed\u30b0\u30a4\u30f3").click()
  File "/Users/murakaminaoki/anaconda3/lib/python3.6/site-packages/selenium/webdriver/remote/webdriver.py", line 421, in find_element_by_link_text
    return self.find_element(by=By.LINK_TEXT, value=link_text)
  File "/Users/murakaminaoki/anaconda3/lib/python3.6/site-packages/selenium/webdriver/remote/webdriver.py", line 957, in find_element
    'value': value})['value']
  File "/Users/murakaminaoki/anaconda3/lib/python3.6/site-packages/selenium/webdriver/remote/webdriver.py", line 314, in execute
    self.error_handler.check_response(response)
  File "/Users/murakaminaoki/anaconda3/lib/python3.6/site-packages/selenium/webdriver/remote/errorhandler.py", line 242, in check_response
    raise exception_class(message, screen, stacktrace)
selenium.common.exceptions.NoSuchElementException: Message: no such element: Unable to locate element: {"method":"link text","selector":"\u30ed\u30b0\u30a4\u30f3"}
  (Session info: headless chrome=67.0.3396.99)
  (Driver info: chromedriver=2.40.565386 (45a059dc425e08165f9a10324bd1380cc13ca363),platform=Mac OS X 10.13.6 x86_64)


During handling of the above exception, another exception occurred:

Traceback (most recent call last):
  File "/Users/murakaminaoki/git/atwiki/atwiki.py", line 40, in <module>
    print("\u4f8b\u5916\u304c\u767a\u751f\u3057\u307e\u3057\u305f\uff08\u30cd\u30c3\u30c8\u30ef\u30fc\u30af\u306b\u7e4b\u304c\u3063\u3066\u3044\u308b\u304b\u3054\u78ba\u8a8d\u304f\u3060\u3055\u3044\uff09")
UnicodeEncodeError: 'ascii' codec can't encode characters in position 0-31: ordinal not in range(128)
Traceback (most recent call last):
  File "/Users/murakaminaoki/git/atwiki/atwiki.py", line 34, in <module>
    driver.find_element_by_name("login").click()
  File "/Users/murakaminaoki/anaconda3/lib/python3.6/site-packages/selenium/webdriver/remote/webdriver.py", line 489, in find_element_by_name
    return self.find_element(by=By.NAME, value=name)
  File "/Users/murakaminaoki/anaconda3/lib/python3.6/site-packages/selenium/webdriver/remote/webdriver.py", line 957, in find_element
    'value': value})['value']
  File "/Users/murakaminaoki/anaconda3/lib/python3.6/site-packages/selenium/webdriver/remote/webdriver.py", line 314, in execute
    self.error_handler.check_response(response)
  File "/Users/murakaminaoki/anaconda3/lib/python3.6/site-packages/selenium/webdriver/remote/errorhandler.py", line 242, in check_response
    raise exception_class(message, screen, stacktrace)
selenium.common.exceptions.NoSuchElementException: Message: no such element: Unable to locate element: {"method":"name","selector":"login"}
  (Session info: headless chrome=67.0.3396.99)
  (Driver info: chromedriver=2.40.565386 (45a059dc425e08165f9a10324bd1380cc13ca363),platform=Mac OS X 10.13.6 x86_64)


During handling of the above exception, another exception occurred:

Traceback (most recent call last):
  File "/Users/murakaminaoki/git/atwiki/atwiki.py", line 40, in <module>
    print("\u4f8b\u5916\u304c\u767a\u751f\u3057\u307e\u3057\u305f\uff08\u30cd\u30c3\u30c8\u30ef\u30fc\u30af\u306b\u7e4b\u304c\u3063\u3066\u3044\u308b\u304b\u3054\u78ba\u8a8d\u304f\u3060\u3055\u3044\uff09")
UnicodeEncodeError: 'ascii' codec can't encode characters in position 0-31: ordinal not in range(128)
Traceback (most recent call last):
  File "/Users/murakaminaoki/git/atwiki/atwiki.py", line 34, in <module>
    driver.find_element_by_name("login").click()
  File "/Users/murakaminaoki/anaconda3/lib/python3.6/site-packages/selenium/webdriver/remote/webdriver.py", line 489, in find_element_by_name
    return self.find_element(by=By.NAME, value=name)
  File "/Users/murakaminaoki/anaconda3/lib/python3.6/site-packages/selenium/webdriver/remote/webdriver.py", line 957, in find_element
    'value': value})['value']
  File "/Users/murakaminaoki/anaconda3/lib/python3.6/site-packages/selenium/webdriver/remote/webdriver.py", line 314, in execute
    self.error_handler.check_response(response)
  File "/Users/murakaminaoki/anaconda3/lib/python3.6/site-packages/selenium/webdriver/remote/errorhandler.py", line 242, in check_response
    raise exception_class(message, screen, stacktrace)
selenium.common.exceptions.NoSuchElementException: Message: no such element: Unable to locate element: {"method":"name","selector":"login"}
  (Session info: headless chrome=67.0.3396.99)
  (Driver info: chromedriver=2.40.565386 (45a059dc425e08165f9a10324bd1380cc13ca363),platform=Mac OS X 10.13.6 x86_64)


During handling of the above exception, another exception occurred:

Traceback (most recent call last):
  File "/Users/murakaminaoki/git/atwiki/atwiki.py", line 40, in <module>
    print("\u4f8b\u5916\u304c\u767a\u751f\u3057\u307e\u3057\u305f\uff08\u30cd\u30c3\u30c8\u30ef\u30fc\u30af\u306b\u7e4b\u304c\u3063\u3066\u3044\u308b\u304b\u3054\u78ba\u8a8d\u304f\u3060\u3055\u3044\uff09")
UnicodeEncodeError: 'ascii' codec can't encode characters in position 0-31: ordinal not in range(128)
Traceback (most recent call last):
  File "/Users/murakaminaoki/git/atwiki/atwiki.py", line 34, in <module>
    driver.find_element_by_name("login").click()
  File "/Users/murakaminaoki/anaconda3/lib/python3.6/site-packages/selenium/webdriver/remote/webdriver.py", line 489, in find_element_by_name
    return self.find_element(by=By.NAME, value=name)
  File "/Users/murakaminaoki/anaconda3/lib/python3.6/site-packages/selenium/webdriver/remote/webdriver.py", line 957, in find_element
    'value': value})['value']
  File "/Users/murakaminaoki/anaconda3/lib/python3.6/site-packages/selenium/webdriver/remote/webdriver.py", line 314, in execute
    self.error_handler.check_response(response)
  File "/Users/murakaminaoki/anaconda3/lib/python3.6/site-packages/selenium/webdriver/remote/errorhandler.py", line 242, in check_response
    raise exception_class(message, screen, stacktrace)
selenium.common.exceptions.NoSuchElementException: Message: no such element: Unable to locate element: {"method":"name","selector":"login"}
  (Session info: headless chrome=67.0.3396.99)
  (Driver info: chromedriver=2.40.565386 (45a059dc425e08165f9a10324bd1380cc13ca363),platform=Mac OS X 10.13.6 x86_64)


During handling of the above exception, another exception occurred:

Traceback (most recent call last):
  File "/Users/murakaminaoki/git/atwiki/atwiki.py", line 40, in <module>
    print("\u4f8b\u5916\u304c\u767a\u751f\u3057\u307e\u3057\u305f\uff08\u30cd\u30c3\u30c8\u30ef\u30fc\u30af\u306b\u7e4b\u304c\u3063\u3066\u3044\u308b\u304b\u3054\u78ba\u8a8d\u304f\u3060\u3055\u3044\uff09")
UnicodeEncodeError: 'ascii' codec can't encode characters in position 0-31: ordinal not in range(128)
Traceback (most recent call last):
  File "/Users/murakaminaoki/git/atwiki/atwiki.py", line 34, in <module>
    driver.find_element_by_name("login").click()
  File "/Users/murakaminaoki/anaconda3/lib/python3.6/site-packages/selenium/webdriver/remote/webdriver.py", line 489, in find_element_by_name
    return self.find_element(by=By.NAME, value=name)
  File "/Users/murakaminaoki/anaconda3/lib/python3.6/site-packages/selenium/webdriver/remote/webdriver.py", line 957, in find_element
    'value': value})['value']
  File "/Users/murakaminaoki/anaconda3/lib/python3.6/site-packages/selenium/webdriver/remote/webdriver.py", line 314, in execute
    self.error_handler.check_response(response)
  File "/Users/murakaminaoki/anaconda3/lib/python3.6/site-packages/selenium/webdriver/remote/errorhandler.py", line 242, in check_response
    raise exception_class(message, screen, stacktrace)
selenium.common.exceptions.NoSuchElementException: Message: no such element: Unable to locate element: {"method":"name","selector":"login"}
  (Session info: headless chrome=67.0.3396.99)
  (Driver info: chromedriver=2.40.565386 (45a059dc425e08165f9a10324bd1380cc13ca363),platform=Mac OS X 10.13.6 x86_64)


During handling of the above exception, another exception occurred:

Traceback (most recent call last):
  File "/Users/murakaminaoki/git/atwiki/atwiki.py", line 40, in <module>
    print("\u4f8b\u5916\u304c\u767a\u751f\u3057\u307e\u3057\u305f\uff08\u30cd\u30c3\u30c8\u30ef\u30fc\u30af\u306b\u7e4b\u304c\u3063\u3066\u3044\u308b\u304b\u3054\u78ba\u8a8d\u304f\u3060\u3055\u3044\uff09")
UnicodeEncodeError: 'ascii' codec can't encode characters in position 0-31: ordinal not in range(128)
Traceback (most recent call last):
  File "/Users/murakaminaoki/git/atwiki/atwiki.py", line 34, in <module>
    driver.find_element_by_name("login").click()
  File "/Users/murakaminaoki/anaconda3/lib/python3.6/site-packages/selenium/webdriver/remote/webdriver.py", line 489, in find_element_by_name
    return self.find_element(by=By.NAME, value=name)
  File "/Users/murakaminaoki/anaconda3/lib/python3.6/site-packages/selenium/webdriver/remote/webdriver.py", line 957, in find_element
    'value': value})['value']
  File "/Users/murakaminaoki/anaconda3/lib/python3.6/site-packages/selenium/webdriver/remote/webdriver.py", line 314, in execute
    self.error_handler.check_response(response)
  File "/Users/murakaminaoki/anaconda3/lib/python3.6/site-packages/selenium/webdriver/remote/errorhandler.py", line 242, in check_response
    raise exception_class(message, screen, stacktrace)
selenium.common.exceptions.NoSuchElementException: Message: no such element: Unable to locate element: {"method":"name","selector":"login"}
  (Session info: headless chrome=67.0.3396.99)
  (Driver info: chromedriver=2.40.565386 (45a059dc425e08165f9a10324bd1380cc13ca363),platform=Mac OS X 10.13.6 x86_64)


During handling of the above exception, another exception occurred:

Traceback (most recent call last):
  File "/Users/murakaminaoki/git/atwiki/atwiki.py", line 40, in <module>
    print("\u4f8b\u5916\u304c\u767a\u751f\u3057\u307e\u3057\u305f\uff08\u30cd\u30c3\u30c8\u30ef\u30fc\u30af\u306b\u7e4b\u304c\u3063\u3066\u3044\u308b\u304b\u3054\u78ba\u8a8d\u304f\u3060\u3055\u3044\uff09")
UnicodeEncodeError: 'ascii' codec can't encode characters in position 0-31: ordinal not in range(128)
Traceback (most recent call last):
  File "/Users/murakaminaoki/git/atwiki/atwiki.py", line 34, in <module>
    driver.find_element_by_name("login").click()
  File "/Users/murakaminaoki/anaconda3/lib/python3.6/site-packages/selenium/webdriver/remote/webdriver.py", line 489, in find_element_by_name
    return self.find_element(by=By.NAME, value=name)
  File "/Users/murakaminaoki/anaconda3/lib/python3.6/site-packages/selenium/webdriver/remote/webdriver.py", line 957, in find_element
    'value': value})['value']
  File "/Users/murakaminaoki/anaconda3/lib/python3.6/site-packages/selenium/webdriver/remote/webdriver.py", line 314, in execute
    self.error_handler.check_response(response)
  File "/Users/murakaminaoki/anaconda3/lib/python3.6/site-packages/selenium/webdriver/remote/errorhandler.py", line 242, in check_response
    raise exception_class(message, screen, stacktrace)
selenium.common.exceptions.NoSuchElementException: Message: no such element: Unable to locate element: {"method":"name","selector":"login"}
  (Session info: headless chrome=67.0.3396.99)
  (Driver info: chromedriver=2.40.565386 (45a059dc425e08165f9a10324bd1380cc13ca363),platform=Mac OS X 10.13.6 x86_64)


During handling of the above exception, another exception occurred:

Traceback (most recent call last):
  File "/Users/murakaminaoki/git/atwiki/atwiki.py", line 40, in <module>
    print("\u4f8b\u5916\u304c\u767a\u751f\u3057\u307e\u3057\u305f\uff08\u30cd\u30c3\u30c8\u30ef\u30fc\u30af\u306b\u7e4b\u304c\u3063\u3066\u3044\u308b\u304b\u3054\u78ba\u8a8d\u304f\u3060\u3055\u3044\uff09")
UnicodeEncodeError: 'ascii' codec can't encode characters in position 0-31: ordinal not in range(128)
Traceback (most recent call last):
  File "/Users/murakaminaoki/git/atwiki/atwiki.py", line 32, in <module>
    driver.find_element_by_name("user").send_keys(user)
  File "/Users/murakaminaoki/anaconda3/lib/python3.6/site-packages/selenium/webdriver/remote/webdriver.py", line 489, in find_element_by_name
    return self.find_element(by=By.NAME, value=name)
  File "/Users/murakaminaoki/anaconda3/lib/python3.6/site-packages/selenium/webdriver/remote/webdriver.py", line 957, in find_element
    'value': value})['value']
  File "/Users/murakaminaoki/anaconda3/lib/python3.6/site-packages/selenium/webdriver/remote/webdriver.py", line 314, in execute
    self.error_handler.check_response(response)
  File "/Users/murakaminaoki/anaconda3/lib/python3.6/site-packages/selenium/webdriver/remote/errorhandler.py", line 242, in check_response
    raise exception_class(message, screen, stacktrace)
selenium.common.exceptions.NoSuchElementException: Message: no such element: Unable to locate element: {"method":"name","selector":"user"}
  (Session info: headless chrome=67.0.3396.99)
  (Driver info: chromedriver=2.40.565386 (45a059dc425e08165f9a10324bd1380cc13ca363),platform=Mac OS X 10.13.6 x86_64)


During handling of the above exception, another exception occurred:

Traceback (most recent call last):
  File "/Users/murakaminaoki/git/atwiki/atwiki.py", line 40, in <module>
    print("\u4f8b\u5916\u304c\u767a\u751f\u3057\u307e\u3057\u305f\uff08\u30cd\u30c3\u30c8\u30ef\u30fc\u30af\u306b\u7e4b\u304c\u3063\u3066\u3044\u308b\u304b\u3054\u78ba\u8a8d\u304f\u3060\u3055\u3044\uff09")
UnicodeEncodeError: 'ascii' codec can't encode characters in position 0-31: ordinal not in range(128)
Traceback (most recent call last):
  File "/Users/murakaminaoki/git/atwiki/atwiki.py", line 32, in <module>
    driver.find_element_by_name("user").send_keys(user)
  File "/Users/murakaminaoki/anaconda3/lib/python3.6/site-packages/selenium/webdriver/remote/webdriver.py", line 489, in find_element_by_name
    return self.find_element(by=By.NAME, value=name)
  File "/Users/murakaminaoki/anaconda3/lib/python3.6/site-packages/selenium/webdriver/remote/webdriver.py", line 957, in find_element
    'value': value})['value']
  File "/Users/murakaminaoki/anaconda3/lib/python3.6/site-packages/selenium/webdriver/remote/webdriver.py", line 314, in execute
    self.error_handler.check_response(response)
  File "/Users/murakaminaoki/anaconda3/lib/python3.6/site-packages/selenium/webdriver/remote/errorhandler.py", line 242, in check_response
    raise exception_class(message, screen, stacktrace)
selenium.common.exceptions.NoSuchElementException: Message: no such element: Unable to locate element: {"method":"name","selector":"user"}
  (Session info: headless chrome=67.0.3396.99)
  (Driver info: chromedriver=2.40.565386 (45a059dc425e08165f9a10324bd1380cc13ca363),platform=Mac OS X 10.13.6 x86_64)


During handling of the above exception, another exception occurred:

Traceback (most recent call last):
  File "/Users/murakaminaoki/git/atwiki/atwiki.py", line 40, in <module>
    print("\u4f8b\u5916\u304c\u767a\u751f\u3057\u307e\u3057\u305f\uff08\u30cd\u30c3\u30c8\u30ef\u30fc\u30af\u306b\u7e4b\u304c\u3063\u3066\u3044\u308b\u304b\u3054\u78ba\u8a8d\u304f\u3060\u3055\u3044\uff09")
UnicodeEncodeError: 'ascii' codec can't encode characters in position 0-31: ordinal not in range(128)
Traceback (most recent call last):
  File "/Users/murakaminaoki/git/atwiki/atwiki.py", line 34, in <module>
    driver.find_element_by_name("login").click()
  File "/Users/murakaminaoki/anaconda3/lib/python3.6/site-packages/selenium/webdriver/remote/webdriver.py", line 489, in find_element_by_name
    return self.find_element(by=By.NAME, value=name)
  File "/Users/murakaminaoki/anaconda3/lib/python3.6/site-packages/selenium/webdriver/remote/webdriver.py", line 957, in find_element
    'value': value})['value']
  File "/Users/murakaminaoki/anaconda3/lib/python3.6/site-packages/selenium/webdriver/remote/webdriver.py", line 314, in execute
    self.error_handler.check_response(response)
  File "/Users/murakaminaoki/anaconda3/lib/python3.6/site-packages/selenium/webdriver/remote/errorhandler.py", line 242, in check_response
    raise exception_class(message, screen, stacktrace)
selenium.common.exceptions.NoSuchElementException: Message: no such element: Unable to locate element: {"method":"name","selector":"login"}
  (Session info: headless chrome=67.0.3396.99)
  (Driver info: chromedriver=2.40.565386 (45a059dc425e08165f9a10324bd1380cc13ca363),platform=Mac OS X 10.13.6 x86_64)


During handling of the above exception, another exception occurred:

Traceback (most recent call last):
  File "/Users/murakaminaoki/git/atwiki/atwiki.py", line 40, in <module>
    print("\u4f8b\u5916\u304c\u767a\u751f\u3057\u307e\u3057\u305f\uff08\u30cd\u30c3\u30c8\u30ef\u30fc\u30af\u306b\u7e4b\u304c\u3063\u3066\u3044\u308b\u304b\u3054\u78ba\u8a8d\u304f\u3060\u3055\u3044\uff09")
UnicodeEncodeError: 'ascii' codec can't encode characters in position 0-31: ordinal not in range(128)
Traceback (most recent call last):
  File "/Users/murakaminaoki/git/atwiki/atwiki.py", line 32, in <module>
    driver.find_element_by_name("user").send_keys(user)
  File "/Users/murakaminaoki/anaconda3/lib/python3.6/site-packages/selenium/webdriver/remote/webdriver.py", line 489, in find_element_by_name
    return self.find_element(by=By.NAME, value=name)
  File "/Users/murakaminaoki/anaconda3/lib/python3.6/site-packages/selenium/webdriver/remote/webdriver.py", line 957, in find_element
    'value': value})['value']
  File "/Users/murakaminaoki/anaconda3/lib/python3.6/site-packages/selenium/webdriver/remote/webdriver.py", line 314, in execute
    self.error_handler.check_response(response)
  File "/Users/murakaminaoki/anaconda3/lib/python3.6/site-packages/selenium/webdriver/remote/errorhandler.py", line 242, in check_response
    raise exception_class(message, screen, stacktrace)
selenium.common.exceptions.NoSuchElementException: Message: no such element: Unable to locate element: {"method":"name","selector":"user"}
  (Session info: headless chrome=67.0.3396.99)
  (Driver info: chromedriver=2.40.565386 (45a059dc425e08165f9a10324bd1380cc13ca363),platform=Mac OS X 10.13.6 x86_64)


During handling of the above exception, another exception occurred:

Traceback (most recent call last):
  File "/Users/murakaminaoki/git/atwiki/atwiki.py", line 40, in <module>
    print("\u4f8b\u5916\u304c\u767a\u751f\u3057\u307e\u3057\u305f\uff08\u30cd\u30c3\u30c8\u30ef\u30fc\u30af\u306b\u7e4b\u304c\u3063\u3066\u3044\u308b\u304b\u3054\u78ba\u8a8d\u304f\u3060\u3055\u3044\uff09")
UnicodeEncodeError: 'ascii' codec can't encode characters in position 0-31: ordinal not in range(128)
Traceback (most recent call last):
  File "/Users/murakaminaoki/git/atwiki/atwiki.py", line 34, in <module>
    driver.find_element_by_name("login").click()
  File "/Users/murakaminaoki/anaconda3/lib/python3.6/site-packages/selenium/webdriver/remote/webdriver.py", line 489, in find_element_by_name
    return self.find_element(by=By.NAME, value=name)
  File "/Users/murakaminaoki/anaconda3/lib/python3.6/site-packages/selenium/webdriver/remote/webdriver.py", line 957, in find_element
    'value': value})['value']
  File "/Users/murakaminaoki/anaconda3/lib/python3.6/site-packages/selenium/webdriver/remote/webdriver.py", line 314, in execute
    self.error_handler.check_response(response)
  File "/Users/murakaminaoki/anaconda3/lib/python3.6/site-packages/selenium/webdriver/remote/errorhandler.py", line 242, in check_response
    raise exception_class(message, screen, stacktrace)
selenium.common.exceptions.NoSuchElementException: Message: no such element: Unable to locate element: {"method":"name","selector":"login"}
  (Session info: headless chrome=67.0.3396.99)
  (Driver info: chromedriver=2.40.565386 (45a059dc425e08165f9a10324bd1380cc13ca363),platform=Mac OS X 10.13.6 x86_64)


During handling of the above exception, another exception occurred:

Traceback (most recent call last):
  File "/Users/murakaminaoki/git/atwiki/atwiki.py", line 40, in <module>
    print("\u4f8b\u5916\u304c\u767a\u751f\u3057\u307e\u3057\u305f\uff08\u30cd\u30c3\u30c8\u30ef\u30fc\u30af\u306b\u7e4b\u304c\u3063\u3066\u3044\u308b\u304b\u3054\u78ba\u8a8d\u304f\u3060\u3055\u3044\uff09")
UnicodeEncodeError: 'ascii' codec can't encode characters in position 0-31: ordinal not in range(128)
Traceback (most recent call last):
  File "/Users/murakaminaoki/git/atwiki/atwiki.py", line 34, in <module>
    driver.find_element_by_name("login").click()
  File "/Users/murakaminaoki/anaconda3/lib/python3.6/site-packages/selenium/webdriver/remote/webdriver.py", line 489, in find_element_by_name
    return self.find_element(by=By.NAME, value=name)
  File "/Users/murakaminaoki/anaconda3/lib/python3.6/site-packages/selenium/webdriver/remote/webdriver.py", line 957, in find_element
    'value': value})['value']
  File "/Users/murakaminaoki/anaconda3/lib/python3.6/site-packages/selenium/webdriver/remote/webdriver.py", line 314, in execute
    self.error_handler.check_response(response)
  File "/Users/murakaminaoki/anaconda3/lib/python3.6/site-packages/selenium/webdriver/remote/errorhandler.py", line 242, in check_response
    raise exception_class(message, screen, stacktrace)
selenium.common.exceptions.NoSuchElementException: Message: no such element: Unable to locate element: {"method":"name","selector":"login"}
  (Session info: headless chrome=67.0.3396.99)
  (Driver info: chromedriver=2.40.565386 (45a059dc425e08165f9a10324bd1380cc13ca363),platform=Mac OS X 10.13.6 x86_64)


During handling of the above exception, another exception occurred:

Traceback (most recent call last):
  File "/Users/murakaminaoki/git/atwiki/atwiki.py", line 40, in <module>
    print("\u4f8b\u5916\u304c\u767a\u751f\u3057\u307e\u3057\u305f\uff08\u30cd\u30c3\u30c8\u30ef\u30fc\u30af\u306b\u7e4b\u304c\u3063\u3066\u3044\u308b\u304b\u3054\u78ba\u8a8d\u304f\u3060\u3055\u3044\uff09")
UnicodeEncodeError: 'ascii' codec can't encode characters in position 0-31: ordinal not in range(128)
Traceback (most recent call last):
  File "/Users/murakaminaoki/git/atwiki/atwiki.py", line 34, in <module>
    driver.find_element_by_name("login").click()
  File "/Users/murakaminaoki/anaconda3/lib/python3.6/site-packages/selenium/webdriver/remote/webdriver.py", line 489, in find_element_by_name
    return self.find_element(by=By.NAME, value=name)
  File "/Users/murakaminaoki/anaconda3/lib/python3.6/site-packages/selenium/webdriver/remote/webdriver.py", line 957, in find_element
    'value': value})['value']
  File "/Users/murakaminaoki/anaconda3/lib/python3.6/site-packages/selenium/webdriver/remote/webdriver.py", line 314, in execute
    self.error_handler.check_response(response)
  File "/Users/murakaminaoki/anaconda3/lib/python3.6/site-packages/selenium/webdriver/remote/errorhandler.py", line 242, in check_response
    raise exception_class(message, screen, stacktrace)
selenium.common.exceptions.NoSuchElementException: Message: no such element: Unable to locate element: {"method":"name","selector":"login"}
  (Session info: headless chrome=67.0.3396.99)
  (Driver info: chromedriver=2.40.565386 (45a059dc425e08165f9a10324bd1380cc13ca363),platform=Mac OS X 10.13.6 x86_64)


During handling of the above exception, another exception occurred:

Traceback (most recent call last):
  File "/Users/murakaminaoki/git/atwiki/atwiki.py", line 40, in <module>
    print("\u4f8b\u5916\u304c\u767a\u751f\u3057\u307e\u3057\u305f\uff08\u30cd\u30c3\u30c8\u30ef\u30fc\u30af\u306b\u7e4b\u304c\u3063\u3066\u3044\u308b\u304b\u3054\u78ba\u8a8d\u304f\u3060\u3055\u3044\uff09")
UnicodeEncodeError: 'ascii' codec can't encode characters in position 0-31: ordinal not in range(128)
Traceback (most recent call last):
  File "/Users/murakaminaoki/git/atwiki/atwiki.py", line 34, in <module>
    driver.find_element_by_name("login").click()
  File "/Users/murakaminaoki/anaconda3/lib/python3.6/site-packages/selenium/webdriver/remote/webdriver.py", line 489, in find_element_by_name
    return self.find_element(by=By.NAME, value=name)
  File "/Users/murakaminaoki/anaconda3/lib/python3.6/site-packages/selenium/webdriver/remote/webdriver.py", line 957, in find_element
    'value': value})['value']
  File "/Users/murakaminaoki/anaconda3/lib/python3.6/site-packages/selenium/webdriver/remote/webdriver.py", line 314, in execute
    self.error_handler.check_response(response)
  File "/Users/murakaminaoki/anaconda3/lib/python3.6/site-packages/selenium/webdriver/remote/errorhandler.py", line 242, in check_response
    raise exception_class(message, screen, stacktrace)
selenium.common.exceptions.NoSuchElementException: Message: no such element: Unable to locate element: {"method":"name","selector":"login"}
  (Session info: headless chrome=67.0.3396.99)
  (Driver info: chromedriver=2.40.565386 (45a059dc425e08165f9a10324bd1380cc13ca363),platform=Mac OS X 10.13.6 x86_64)


During handling of the above exception, another exception occurred:

Traceback (most recent call last):
  File "/Users/murakaminaoki/git/atwiki/atwiki.py", line 40, in <module>
    print("\u4f8b\u5916\u304c\u767a\u751f\u3057\u307e\u3057\u305f\uff08\u30cd\u30c3\u30c8\u30ef\u30fc\u30af\u306b\u7e4b\u304c\u3063\u3066\u3044\u308b\u304b\u3054\u78ba\u8a8d\u304f\u3060\u3055\u3044\uff09")
UnicodeEncodeError: 'ascii' codec can't encode characters in position 0-31: ordinal not in range(128)
Traceback (most recent call last):
  File "/Users/murakaminaoki/git/atwiki/atwiki.py", line 34, in <module>
    driver.find_element_by_name("login").click()
  File "/Users/murakaminaoki/anaconda3/lib/python3.6/site-packages/selenium/webdriver/remote/webdriver.py", line 489, in find_element_by_name
    return self.find_element(by=By.NAME, value=name)
  File "/Users/murakaminaoki/anaconda3/lib/python3.6/site-packages/selenium/webdriver/remote/webdriver.py", line 957, in find_element
    'value': value})['value']
  File "/Users/murakaminaoki/anaconda3/lib/python3.6/site-packages/selenium/webdriver/remote/webdriver.py", line 314, in execute
    self.error_handler.check_response(response)
  File "/Users/murakaminaoki/anaconda3/lib/python3.6/site-packages/selenium/webdriver/remote/errorhandler.py", line 242, in check_response
    raise exception_class(message, screen, stacktrace)
selenium.common.exceptions.NoSuchElementException: Message: no such element: Unable to locate element: {"method":"name","selector":"login"}
  (Session info: headless chrome=67.0.3396.99)
  (Driver info: chromedriver=2.40.565386 (45a059dc425e08165f9a10324bd1380cc13ca363),platform=Mac OS X 10.13.6 x86_64)


During handling of the above exception, another exception occurred:

Traceback (most recent call last):
  File "/Users/murakaminaoki/git/atwiki/atwiki.py", line 40, in <module>
    print("\u4f8b\u5916\u304c\u767a\u751f\u3057\u307e\u3057\u305f\uff08\u30cd\u30c3\u30c8\u30ef\u30fc\u30af\u306b\u7e4b\u304c\u3063\u3066\u3044\u308b\u304b\u3054\u78ba\u8a8d\u304f\u3060\u3055\u3044\uff09")
UnicodeEncodeError: 'ascii' codec can't encode characters in position 0-31: ordinal not in range(128)
Traceback (most recent call last):
  File "/Users/murakaminaoki/git/atwiki/atwiki.py", line 34, in <module>
    driver.find_element_by_name("login").click()
  File "/Users/murakaminaoki/anaconda3/lib/python3.6/site-packages/selenium/webdriver/remote/webdriver.py", line 489, in find_element_by_name
    return self.find_element(by=By.NAME, value=name)
  File "/Users/murakaminaoki/anaconda3/lib/python3.6/site-packages/selenium/webdriver/remote/webdriver.py", line 957, in find_element
    'value': value})['value']
  File "/Users/murakaminaoki/anaconda3/lib/python3.6/site-packages/selenium/webdriver/remote/webdriver.py", line 314, in execute
    self.error_handler.check_response(response)
  File "/Users/murakaminaoki/anaconda3/lib/python3.6/site-packages/selenium/webdriver/remote/errorhandler.py", line 242, in check_response
    raise exception_class(message, screen, stacktrace)
selenium.common.exceptions.NoSuchElementException: Message: no such element: Unable to locate element: {"method":"name","selector":"login"}
  (Session info: headless chrome=67.0.3396.99)
  (Driver info: chromedriver=2.40.565386 (45a059dc425e08165f9a10324bd1380cc13ca363),platform=Mac OS X 10.13.6 x86_64)


During handling of the above exception, another exception occurred:

Traceback (most recent call last):
  File "/Users/murakaminaoki/git/atwiki/atwiki.py", line 40, in <module>
    print("\u4f8b\u5916\u304c\u767a\u751f\u3057\u307e\u3057\u305f\uff08\u30cd\u30c3\u30c8\u30ef\u30fc\u30af\u306b\u7e4b\u304c\u3063\u3066\u3044\u308b\u304b\u3054\u78ba\u8a8d\u304f\u3060\u3055\u3044\uff09")
UnicodeEncodeError: 'ascii' codec can't encode characters in position 0-31: ordinal not in range(128)
Traceback (most recent call last):
  File "/Users/murakaminaoki/git/atwiki/atwiki.py", line 34, in <module>
    driver.find_element_by_name("login").click()
  File "/Users/murakaminaoki/anaconda3/lib/python3.6/site-packages/selenium/webdriver/remote/webdriver.py", line 489, in find_element_by_name
    return self.find_element(by=By.NAME, value=name)
  File "/Users/murakaminaoki/anaconda3/lib/python3.6/site-packages/selenium/webdriver/remote/webdriver.py", line 957, in find_element
    'value': value})['value']
  File "/Users/murakaminaoki/anaconda3/lib/python3.6/site-packages/selenium/webdriver/remote/webdriver.py", line 314, in execute
    self.error_handler.check_response(response)
  File "/Users/murakaminaoki/anaconda3/lib/python3.6/site-packages/selenium/webdriver/remote/errorhandler.py", line 242, in check_response
    raise exception_class(message, screen, stacktrace)
selenium.common.exceptions.NoSuchElementException: Message: no such element: Unable to locate element: {"method":"name","selector":"login"}
  (Session info: headless chrome=67.0.3396.99)
  (Driver info: chromedriver=2.40.565386 (45a059dc425e08165f9a10324bd1380cc13ca363),platform=Mac OS X 10.13.6 x86_64)


During handling of the above exception, another exception occurred:

Traceback (most recent call last):
  File "/Users/murakaminaoki/git/atwiki/atwiki.py", line 40, in <module>
    print("\u4f8b\u5916\u304c\u767a\u751f\u3057\u307e\u3057\u305f\uff08\u30cd\u30c3\u30c8\u30ef\u30fc\u30af\u306b\u7e4b\u304c\u3063\u3066\u3044\u308b\u304b\u3054\u78ba\u8a8d\u304f\u3060\u3055\u3044\uff09")
UnicodeEncodeError: 'ascii' codec can't encode characters in position 0-31: ordinal not in range(128)
Traceback (most recent call last):
  File "/Users/murakaminaoki/git/atwiki/atwiki.py", line 34, in <module>
    driver.find_element_by_name("login").click()
  File "/Users/murakaminaoki/anaconda3/lib/python3.6/site-packages/selenium/webdriver/remote/webdriver.py", line 489, in find_element_by_name
    return self.find_element(by=By.NAME, value=name)
  File "/Users/murakaminaoki/anaconda3/lib/python3.6/site-packages/selenium/webdriver/remote/webdriver.py", line 957, in find_element
    'value': value})['value']
  File "/Users/murakaminaoki/anaconda3/lib/python3.6/site-packages/selenium/webdriver/remote/webdriver.py", line 314, in execute
    self.error_handler.check_response(response)
  File "/Users/murakaminaoki/anaconda3/lib/python3.6/site-packages/selenium/webdriver/remote/errorhandler.py", line 242, in check_response
    raise exception_class(message, screen, stacktrace)
selenium.common.exceptions.NoSuchElementException: Message: no such element: Unable to locate element: {"method":"name","selector":"login"}
  (Session info: headless chrome=67.0.3396.99)
  (Driver info: chromedriver=2.40.565386 (45a059dc425e08165f9a10324bd1380cc13ca363),platform=Mac OS X 10.13.6 x86_64)


During handling of the above exception, another exception occurred:

Traceback (most recent call last):
  File "/Users/murakaminaoki/git/atwiki/atwiki.py", line 40, in <module>
    print("\u4f8b\u5916\u304c\u767a\u751f\u3057\u307e\u3057\u305f\uff08\u30cd\u30c3\u30c8\u30ef\u30fc\u30af\u306b\u7e4b\u304c\u3063\u3066\u3044\u308b\u304b\u3054\u78ba\u8a8d\u304f\u3060\u3055\u3044\uff09")
UnicodeEncodeError: 'ascii' codec can't encode characters in position 0-31: ordinal not in range(128)
Traceback (most recent call last):
  File "/Users/murakaminaoki/git/atwiki/atwiki.py", line 34, in <module>
    driver.find_element_by_name("login").click()
  File "/Users/murakaminaoki/anaconda3/lib/python3.6/site-packages/selenium/webdriver/remote/webdriver.py", line 489, in find_element_by_name
    return self.find_element(by=By.NAME, value=name)
  File "/Users/murakaminaoki/anaconda3/lib/python3.6/site-packages/selenium/webdriver/remote/webdriver.py", line 957, in find_element
    'value': value})['value']
  File "/Users/murakaminaoki/anaconda3/lib/python3.6/site-packages/selenium/webdriver/remote/webdriver.py", line 314, in execute
    self.error_handler.check_response(response)
  File "/Users/murakaminaoki/anaconda3/lib/python3.6/site-packages/selenium/webdriver/remote/errorhandler.py", line 242, in check_response
    raise exception_class(message, screen, stacktrace)
selenium.common.exceptions.NoSuchElementException: Message: no such element: Unable to locate element: {"method":"name","selector":"login"}
  (Session info: headless chrome=67.0.3396.99)
  (Driver info: chromedriver=2.40.565386 (45a059dc425e08165f9a10324bd1380cc13ca363),platform=Mac OS X 10.13.6 x86_64)


During handling of the above exception, another exception occurred:

Traceback (most recent call last):
  File "/Users/murakaminaoki/git/atwiki/atwiki.py", line 40, in <module>
    print("\u4f8b\u5916\u304c\u767a\u751f\u3057\u307e\u3057\u305f\uff08\u30cd\u30c3\u30c8\u30ef\u30fc\u30af\u306b\u7e4b\u304c\u3063\u3066\u3044\u308b\u304b\u3054\u78ba\u8a8d\u304f\u3060\u3055\u3044\uff09")
UnicodeEncodeError: 'ascii' codec can't encode characters in position 0-31: ordinal not in range(128)
Traceback (most recent call last):
  File "/Users/murakaminaoki/git/atwiki/atwiki.py", line 34, in <module>
    driver.find_element_by_name("login").click()
  File "/Users/murakaminaoki/anaconda3/lib/python3.6/site-packages/selenium/webdriver/remote/webdriver.py", line 489, in find_element_by_name
    return self.find_element(by=By.NAME, value=name)
  File "/Users/murakaminaoki/anaconda3/lib/python3.6/site-packages/selenium/webdriver/remote/webdriver.py", line 957, in find_element
    'value': value})['value']
  File "/Users/murakaminaoki/anaconda3/lib/python3.6/site-packages/selenium/webdriver/remote/webdriver.py", line 314, in execute
    self.error_handler.check_response(response)
  File "/Users/murakaminaoki/anaconda3/lib/python3.6/site-packages/selenium/webdriver/remote/errorhandler.py", line 242, in check_response
    raise exception_class(message, screen, stacktrace)
selenium.common.exceptions.NoSuchElementException: Message: no such element: Unable to locate element: {"method":"name","selector":"login"}
  (Session info: headless chrome=67.0.3396.99)
  (Driver info: chromedriver=2.40.565386 (45a059dc425e08165f9a10324bd1380cc13ca363),platform=Mac OS X 10.13.6 x86_64)


During handling of the above exception, another exception occurred:

Traceback (most recent call last):
  File "/Users/murakaminaoki/git/atwiki/atwiki.py", line 40, in <module>
    print("\u4f8b\u5916\u304c\u767a\u751f\u3057\u307e\u3057\u305f\uff08\u30cd\u30c3\u30c8\u30ef\u30fc\u30af\u306b\u7e4b\u304c\u3063\u3066\u3044\u308b\u304b\u3054\u78ba\u8a8d\u304f\u3060\u3055\u3044\uff09")
UnicodeEncodeError: 'ascii' codec can't encode characters in position 0-31: ordinal not in range(128)
Traceback (most recent call last):
  File "/Users/murakaminaoki/git/atwiki/atwiki.py", line 34, in <module>
    driver.find_element_by_name("login").click()
  File "/Users/murakaminaoki/anaconda3/lib/python3.6/site-packages/selenium/webdriver/remote/webdriver.py", line 489, in find_element_by_name
    return self.find_element(by=By.NAME, value=name)
  File "/Users/murakaminaoki/anaconda3/lib/python3.6/site-packages/selenium/webdriver/remote/webdriver.py", line 957, in find_element
    'value': value})['value']
  File "/Users/murakaminaoki/anaconda3/lib/python3.6/site-packages/selenium/webdriver/remote/webdriver.py", line 314, in execute
    self.error_handler.check_response(response)
  File "/Users/murakaminaoki/anaconda3/lib/python3.6/site-packages/selenium/webdriver/remote/errorhandler.py", line 242, in check_response
    raise exception_class(message, screen, stacktrace)
selenium.common.exceptions.NoSuchElementException: Message: no such element: Unable to locate element: {"method":"name","selector":"login"}
  (Session info: headless chrome=67.0.3396.99)
  (Driver info: chromedriver=2.40.565386 (45a059dc425e08165f9a10324bd1380cc13ca363),platform=Mac OS X 10.13.6 x86_64)


During handling of the above exception, another exception occurred:

Traceback (most recent call last):
  File "/Users/murakaminaoki/git/atwiki/atwiki.py", line 40, in <module>
    print("\u4f8b\u5916\u304c\u767a\u751f\u3057\u307e\u3057\u305f\uff08\u30cd\u30c3\u30c8\u30ef\u30fc\u30af\u306b\u7e4b\u304c\u3063\u3066\u3044\u308b\u304b\u3054\u78ba\u8a8d\u304f\u3060\u3055\u3044\uff09")
UnicodeEncodeError: 'ascii' codec can't encode characters in position 0-31: ordinal not in range(128)
Traceback (most recent call last):
  File "/Users/murakaminaoki/git/atwiki/atwiki.py", line 31, in <module>
    driver.find_element_by_link_text("\u30ed\u30b0\u30a4\u30f3").click()
  File "/Users/murakaminaoki/anaconda3/lib/python3.6/site-packages/selenium/webdriver/remote/webdriver.py", line 421, in find_element_by_link_text
    return self.find_element(by=By.LINK_TEXT, value=link_text)
  File "/Users/murakaminaoki/anaconda3/lib/python3.6/site-packages/selenium/webdriver/remote/webdriver.py", line 957, in find_element
    'value': value})['value']
  File "/Users/murakaminaoki/anaconda3/lib/python3.6/site-packages/selenium/webdriver/remote/webdriver.py", line 314, in execute
    self.error_handler.check_response(response)
  File "/Users/murakaminaoki/anaconda3/lib/python3.6/site-packages/selenium/webdriver/remote/errorhandler.py", line 242, in check_response
    raise exception_class(message, screen, stacktrace)
selenium.common.exceptions.NoSuchElementException: Message: no such element: Unable to locate element: {"method":"link text","selector":"\u30ed\u30b0\u30a4\u30f3"}
  (Session info: headless chrome=67.0.3396.99)
  (Driver info: chromedriver=2.40.565386 (45a059dc425e08165f9a10324bd1380cc13ca363),platform=Mac OS X 10.13.6 x86_64)


During handling of the above exception, another exception occurred:

Traceback (most recent call last):
  File "/Users/murakaminaoki/git/atwiki/atwiki.py", line 40, in <module>
    print("\u4f8b\u5916\u304c\u767a\u751f\u3057\u307e\u3057\u305f\uff08\u30cd\u30c3\u30c8\u30ef\u30fc\u30af\u306b\u7e4b\u304c\u3063\u3066\u3044\u308b\u304b\u3054\u78ba\u8a8d\u304f\u3060\u3055\u3044\uff09")
UnicodeEncodeError: 'ascii' codec can't encode characters in position 0-31: ordinal not in range(128)
Traceback (most recent call last):
  File "/Users/murakaminaoki/git/atwiki/atwiki.py", line 34, in <module>
    driver.find_element_by_name("login").click()
  File "/Users/murakaminaoki/anaconda3/lib/python3.6/site-packages/selenium/webdriver/remote/webdriver.py", line 489, in find_element_by_name
    return self.find_element(by=By.NAME, value=name)
  File "/Users/murakaminaoki/anaconda3/lib/python3.6/site-packages/selenium/webdriver/remote/webdriver.py", line 957, in find_element
    'value': value})['value']
  File "/Users/murakaminaoki/anaconda3/lib/python3.6/site-packages/selenium/webdriver/remote/webdriver.py", line 314, in execute
    self.error_handler.check_response(response)
  File "/Users/murakaminaoki/anaconda3/lib/python3.6/site-packages/selenium/webdriver/remote/errorhandler.py", line 242, in check_response
    raise exception_class(message, screen, stacktrace)
selenium.common.exceptions.NoSuchElementException: Message: no such element: Unable to locate element: {"method":"name","selector":"login"}
  (Session info: headless chrome=67.0.3396.99)
  (Driver info: chromedriver=2.40.565386 (45a059dc425e08165f9a10324bd1380cc13ca363),platform=Mac OS X 10.13.6 x86_64)


During handling of the above exception, another exception occurred:

Traceback (most recent call last):
  File "/Users/murakaminaoki/git/atwiki/atwiki.py", line 40, in <module>
    print("\u4f8b\u5916\u304c\u767a\u751f\u3057\u307e\u3057\u305f\uff08\u30cd\u30c3\u30c8\u30ef\u30fc\u30af\u306b\u7e4b\u304c\u3063\u3066\u3044\u308b\u304b\u3054\u78ba\u8a8d\u304f\u3060\u3055\u3044\uff09")
UnicodeEncodeError: 'ascii' codec can't encode characters in position 0-31: ordinal not in range(128)
Traceback (most recent call last):
  File "/Users/murakaminaoki/git/atwiki/atwiki.py", line 34, in <module>
    driver.find_element_by_name("login").click()
  File "/Users/murakaminaoki/anaconda3/lib/python3.6/site-packages/selenium/webdriver/remote/webdriver.py", line 489, in find_element_by_name
    return self.find_element(by=By.NAME, value=name)
  File "/Users/murakaminaoki/anaconda3/lib/python3.6/site-packages/selenium/webdriver/remote/webdriver.py", line 957, in find_element
    'value': value})['value']
  File "/Users/murakaminaoki/anaconda3/lib/python3.6/site-packages/selenium/webdriver/remote/webdriver.py", line 314, in execute
    self.error_handler.check_response(response)
  File "/Users/murakaminaoki/anaconda3/lib/python3.6/site-packages/selenium/webdriver/remote/errorhandler.py", line 242, in check_response
    raise exception_class(message, screen, stacktrace)
selenium.common.exceptions.NoSuchElementException: Message: no such element: Unable to locate element: {"method":"name","selector":"login"}
  (Session info: headless chrome=67.0.3396.99)
  (Driver info: chromedriver=2.40.565386 (45a059dc425e08165f9a10324bd1380cc13ca363),platform=Mac OS X 10.13.6 x86_64)


During handling of the above exception, another exception occurred:

Traceback (most recent call last):
  File "/Users/murakaminaoki/git/atwiki/atwiki.py", line 40, in <module>
    print("\u4f8b\u5916\u304c\u767a\u751f\u3057\u307e\u3057\u305f\uff08\u30cd\u30c3\u30c8\u30ef\u30fc\u30af\u306b\u7e4b\u304c\u3063\u3066\u3044\u308b\u304b\u3054\u78ba\u8a8d\u304f\u3060\u3055\u3044\uff09")
UnicodeEncodeError: 'ascii' codec can't encode characters in position 0-31: ordinal not in range(128)
Traceback (most recent call last):
  File "/Users/murakaminaoki/git/atwiki/atwiki.py", line 31, in <module>
    driver.find_element_by_link_text("\u30ed\u30b0\u30a4\u30f3").click()
  File "/Users/murakaminaoki/anaconda3/lib/python3.6/site-packages/selenium/webdriver/remote/webdriver.py", line 421, in find_element_by_link_text
    return self.find_element(by=By.LINK_TEXT, value=link_text)
  File "/Users/murakaminaoki/anaconda3/lib/python3.6/site-packages/selenium/webdriver/remote/webdriver.py", line 957, in find_element
    'value': value})['value']
  File "/Users/murakaminaoki/anaconda3/lib/python3.6/site-packages/selenium/webdriver/remote/webdriver.py", line 314, in execute
    self.error_handler.check_response(response)
  File "/Users/murakaminaoki/anaconda3/lib/python3.6/site-packages/selenium/webdriver/remote/errorhandler.py", line 242, in check_response
    raise exception_class(message, screen, stacktrace)
selenium.common.exceptions.NoSuchElementException: Message: no such element: Unable to locate element: {"method":"link text","selector":"\u30ed\u30b0\u30a4\u30f3"}
  (Session info: headless chrome=67.0.3396.99)
  (Driver info: chromedriver=2.40.565386 (45a059dc425e08165f9a10324bd1380cc13ca363),platform=Mac OS X 10.13.6 x86_64)


During handling of the above exception, another exception occurred:

Traceback (most recent call last):
  File "/Users/murakaminaoki/git/atwiki/atwiki.py", line 40, in <module>
    print("\u4f8b\u5916\u304c\u767a\u751f\u3057\u307e\u3057\u305f\uff08\u30cd\u30c3\u30c8\u30ef\u30fc\u30af\u306b\u7e4b\u304c\u3063\u3066\u3044\u308b\u304b\u3054\u78ba\u8a8d\u304f\u3060\u3055\u3044\uff09")
UnicodeEncodeError: 'ascii' codec can't encode characters in position 0-31: ordinal not in range(128)
Traceback (most recent call last):
  File "/Users/murakaminaoki/git/atwiki/atwiki.py", line 32, in <module>
    driver.find_element_by_name("user").send_keys(user)
  File "/Users/murakaminaoki/anaconda3/lib/python3.6/site-packages/selenium/webdriver/remote/webdriver.py", line 489, in find_element_by_name
    return self.find_element(by=By.NAME, value=name)
  File "/Users/murakaminaoki/anaconda3/lib/python3.6/site-packages/selenium/webdriver/remote/webdriver.py", line 957, in find_element
    'value': value})['value']
  File "/Users/murakaminaoki/anaconda3/lib/python3.6/site-packages/selenium/webdriver/remote/webdriver.py", line 314, in execute
    self.error_handler.check_response(response)
  File "/Users/murakaminaoki/anaconda3/lib/python3.6/site-packages/selenium/webdriver/remote/errorhandler.py", line 242, in check_response
    raise exception_class(message, screen, stacktrace)
selenium.common.exceptions.NoSuchElementException: Message: no such element: Unable to locate element: {"method":"name","selector":"user"}
  (Session info: headless chrome=67.0.3396.99)
  (Driver info: chromedriver=2.40.565386 (45a059dc425e08165f9a10324bd1380cc13ca363),platform=Mac OS X 10.13.6 x86_64)


During handling of the above exception, another exception occurred:

Traceback (most recent call last):
  File "/Users/murakaminaoki/git/atwiki/atwiki.py", line 40, in <module>
    print("\u4f8b\u5916\u304c\u767a\u751f\u3057\u307e\u3057\u305f\uff08\u30cd\u30c3\u30c8\u30ef\u30fc\u30af\u306b\u7e4b\u304c\u3063\u3066\u3044\u308b\u304b\u3054\u78ba\u8a8d\u304f\u3060\u3055\u3044\uff09")
UnicodeEncodeError: 'ascii' codec can't encode characters in position 0-31: ordinal not in range(128)
Traceback (most recent call last):
  File "/Users/murakaminaoki/git/atwiki/atwiki.py", line 34, in <module>
    driver.find_element_by_name("login").click()
  File "/Users/murakaminaoki/anaconda3/lib/python3.6/site-packages/selenium/webdriver/remote/webdriver.py", line 489, in find_element_by_name
    return self.find_element(by=By.NAME, value=name)
  File "/Users/murakaminaoki/anaconda3/lib/python3.6/site-packages/selenium/webdriver/remote/webdriver.py", line 957, in find_element
    'value': value})['value']
  File "/Users/murakaminaoki/anaconda3/lib/python3.6/site-packages/selenium/webdriver/remote/webdriver.py", line 314, in execute
    self.error_handler.check_response(response)
  File "/Users/murakaminaoki/anaconda3/lib/python3.6/site-packages/selenium/webdriver/remote/errorhandler.py", line 242, in check_response
    raise exception_class(message, screen, stacktrace)
selenium.common.exceptions.NoSuchElementException: Message: no such element: Unable to locate element: {"method":"name","selector":"login"}
  (Session info: headless chrome=67.0.3396.99)
  (Driver info: chromedriver=2.40.565386 (45a059dc425e08165f9a10324bd1380cc13ca363),platform=Mac OS X 10.13.6 x86_64)


During handling of the above exception, another exception occurred:

Traceback (most recent call last):
  File "/Users/murakaminaoki/git/atwiki/atwiki.py", line 40, in <module>
    print("\u4f8b\u5916\u304c\u767a\u751f\u3057\u307e\u3057\u305f\uff08\u30cd\u30c3\u30c8\u30ef\u30fc\u30af\u306b\u7e4b\u304c\u3063\u3066\u3044\u308b\u304b\u3054\u78ba\u8a8d\u304f\u3060\u3055\u3044\uff09")
UnicodeEncodeError: 'ascii' codec can't encode characters in position 0-31: ordinal not in range(128)
Traceback (most recent call last):
  File "/Users/murakaminaoki/git/atwiki/atwiki.py", line 34, in <module>
    driver.find_element_by_name("login").click()
  File "/Users/murakaminaoki/anaconda3/lib/python3.6/site-packages/selenium/webdriver/remote/webdriver.py", line 489, in find_element_by_name
    return self.find_element(by=By.NAME, value=name)
  File "/Users/murakaminaoki/anaconda3/lib/python3.6/site-packages/selenium/webdriver/remote/webdriver.py", line 957, in find_element
    'value': value})['value']
  File "/Users/murakaminaoki/anaconda3/lib/python3.6/site-packages/selenium/webdriver/remote/webdriver.py", line 314, in execute
    self.error_handler.check_response(response)
  File "/Users/murakaminaoki/anaconda3/lib/python3.6/site-packages/selenium/webdriver/remote/errorhandler.py", line 242, in check_response
    raise exception_class(message, screen, stacktrace)
selenium.common.exceptions.NoSuchElementException: Message: no such element: Unable to locate element: {"method":"name","selector":"login"}
  (Session info: headless chrome=67.0.3396.99)
  (Driver info: chromedriver=2.40.565386 (45a059dc425e08165f9a10324bd1380cc13ca363),platform=Mac OS X 10.13.6 x86_64)


During handling of the above exception, another exception occurred:

Traceback (most recent call last):
  File "/Users/murakaminaoki/git/atwiki/atwiki.py", line 40, in <module>
    print("\u4f8b\u5916\u304c\u767a\u751f\u3057\u307e\u3057\u305f\uff08\u30cd\u30c3\u30c8\u30ef\u30fc\u30af\u306b\u7e4b\u304c\u3063\u3066\u3044\u308b\u304b\u3054\u78ba\u8a8d\u304f\u3060\u3055\u3044\uff09")
UnicodeEncodeError: 'ascii' codec can't encode characters in position 0-31: ordinal not in range(128)
Traceback (most recent call last):
  File "/Users/murakaminaoki/git/atwiki/atwiki.py", line 34, in <module>
    driver.find_element_by_name("login").click()
  File "/Users/murakaminaoki/anaconda3/lib/python3.6/site-packages/selenium/webdriver/remote/webdriver.py", line 489, in find_element_by_name
    return self.find_element(by=By.NAME, value=name)
  File "/Users/murakaminaoki/anaconda3/lib/python3.6/site-packages/selenium/webdriver/remote/webdriver.py", line 957, in find_element
    'value': value})['value']
  File "/Users/murakaminaoki/anaconda3/lib/python3.6/site-packages/selenium/webdriver/remote/webdriver.py", line 314, in execute
    self.error_handler.check_response(response)
  File "/Users/murakaminaoki/anaconda3/lib/python3.6/site-packages/selenium/webdriver/remote/errorhandler.py", line 242, in check_response
    raise exception_class(message, screen, stacktrace)
selenium.common.exceptions.NoSuchElementException: Message: no such element: Unable to locate element: {"method":"name","selector":"login"}
  (Session info: headless chrome=67.0.3396.99)
  (Driver info: chromedriver=2.40.565386 (45a059dc425e08165f9a10324bd1380cc13ca363),platform=Mac OS X 10.13.6 x86_64)


During handling of the above exception, another exception occurred:

Traceback (most recent call last):
  File "/Users/murakaminaoki/git/atwiki/atwiki.py", line 40, in <module>
    print("\u4f8b\u5916\u304c\u767a\u751f\u3057\u307e\u3057\u305f\uff08\u30cd\u30c3\u30c8\u30ef\u30fc\u30af\u306b\u7e4b\u304c\u3063\u3066\u3044\u308b\u304b\u3054\u78ba\u8a8d\u304f\u3060\u3055\u3044\uff09")
UnicodeEncodeError: 'ascii' codec can't encode characters in position 0-31: ordinal not in range(128)
Traceback (most recent call last):
  File "/Users/murakaminaoki/git/atwiki/atwiki.py", line 34, in <module>
    driver.find_element_by_name("login").click()
  File "/Users/murakaminaoki/anaconda3/lib/python3.6/site-packages/selenium/webdriver/remote/webdriver.py", line 489, in find_element_by_name
    return self.find_element(by=By.NAME, value=name)
  File "/Users/murakaminaoki/anaconda3/lib/python3.6/site-packages/selenium/webdriver/remote/webdriver.py", line 957, in find_element
    'value': value})['value']
  File "/Users/murakaminaoki/anaconda3/lib/python3.6/site-packages/selenium/webdriver/remote/webdriver.py", line 314, in execute
    self.error_handler.check_response(response)
  File "/Users/murakaminaoki/anaconda3/lib/python3.6/site-packages/selenium/webdriver/remote/errorhandler.py", line 242, in check_response
    raise exception_class(message, screen, stacktrace)
selenium.common.exceptions.NoSuchElementException: Message: no such element: Unable to locate element: {"method":"name","selector":"login"}
  (Session info: headless chrome=68.0.3440.106)
  (Driver info: chromedriver=2.40.565386 (45a059dc425e08165f9a10324bd1380cc13ca363),platform=Mac OS X 10.13.6 x86_64)


During handling of the above exception, another exception occurred:

Traceback (most recent call last):
  File "/Users/murakaminaoki/git/atwiki/atwiki.py", line 40, in <module>
    print("\u4f8b\u5916\u304c\u767a\u751f\u3057\u307e\u3057\u305f\uff08\u30cd\u30c3\u30c8\u30ef\u30fc\u30af\u306b\u7e4b\u304c\u3063\u3066\u3044\u308b\u304b\u3054\u78ba\u8a8d\u304f\u3060\u3055\u3044\uff09")
UnicodeEncodeError: 'ascii' codec can't encode characters in position 0-31: ordinal not in range(128)
Traceback (most recent call last):
  File "/Users/murakaminaoki/git/atwiki/atwiki.py", line 34, in <module>
    driver.find_element_by_name("login").click()
  File "/Users/murakaminaoki/anaconda3/lib/python3.6/site-packages/selenium/webdriver/remote/webdriver.py", line 489, in find_element_by_name
    return self.find_element(by=By.NAME, value=name)
  File "/Users/murakaminaoki/anaconda3/lib/python3.6/site-packages/selenium/webdriver/remote/webdriver.py", line 957, in find_element
    'value': value})['value']
  File "/Users/murakaminaoki/anaconda3/lib/python3.6/site-packages/selenium/webdriver/remote/webdriver.py", line 314, in execute
    self.error_handler.check_response(response)
  File "/Users/murakaminaoki/anaconda3/lib/python3.6/site-packages/selenium/webdriver/remote/errorhandler.py", line 242, in check_response
    raise exception_class(message, screen, stacktrace)
selenium.common.exceptions.NoSuchElementException: Message: no such element: Unable to locate element: {"method":"name","selector":"login"}
  (Session info: headless chrome=68.0.3440.106)
  (Driver info: chromedriver=2.40.565386 (45a059dc425e08165f9a10324bd1380cc13ca363),platform=Mac OS X 10.13.6 x86_64)


During handling of the above exception, another exception occurred:

Traceback (most recent call last):
  File "/Users/murakaminaoki/git/atwiki/atwiki.py", line 40, in <module>
    print("\u4f8b\u5916\u304c\u767a\u751f\u3057\u307e\u3057\u305f\uff08\u30cd\u30c3\u30c8\u30ef\u30fc\u30af\u306b\u7e4b\u304c\u3063\u3066\u3044\u308b\u304b\u3054\u78ba\u8a8d\u304f\u3060\u3055\u3044\uff09")
UnicodeEncodeError: 'ascii' codec can't encode characters in position 0-31: ordinal not in range(128)
Traceback (most recent call last):
  File "/Users/murakaminaoki/git/atwiki/atwiki.py", line 34, in <module>
    driver.find_element_by_name("login").click()
  File "/Users/murakaminaoki/anaconda3/lib/python3.6/site-packages/selenium/webdriver/remote/webdriver.py", line 489, in find_element_by_name
    return self.find_element(by=By.NAME, value=name)
  File "/Users/murakaminaoki/anaconda3/lib/python3.6/site-packages/selenium/webdriver/remote/webdriver.py", line 957, in find_element
    'value': value})['value']
  File "/Users/murakaminaoki/anaconda3/lib/python3.6/site-packages/selenium/webdriver/remote/webdriver.py", line 314, in execute
    self.error_handler.check_response(response)
  File "/Users/murakaminaoki/anaconda3/lib/python3.6/site-packages/selenium/webdriver/remote/errorhandler.py", line 242, in check_response
    raise exception_class(message, screen, stacktrace)
selenium.common.exceptions.NoSuchElementException: Message: no such element: Unable to locate element: {"method":"name","selector":"login"}
  (Session info: headless chrome=68.0.3440.106)
  (Driver info: chromedriver=2.40.565386 (45a059dc425e08165f9a10324bd1380cc13ca363),platform=Mac OS X 10.13.6 x86_64)


During handling of the above exception, another exception occurred:

Traceback (most recent call last):
  File "/Users/murakaminaoki/git/atwiki/atwiki.py", line 40, in <module>
    print("\u4f8b\u5916\u304c\u767a\u751f\u3057\u307e\u3057\u305f\uff08\u30cd\u30c3\u30c8\u30ef\u30fc\u30af\u306b\u7e4b\u304c\u3063\u3066\u3044\u308b\u304b\u3054\u78ba\u8a8d\u304f\u3060\u3055\u3044\uff09")
UnicodeEncodeError: 'ascii' codec can't encode characters in position 0-31: ordinal not in range(128)
Traceback (most recent call last):
  File "/Users/murakaminaoki/git/atwiki/atwiki.py", line 34, in <module>
    driver.find_element_by_name("login").click()
  File "/Users/murakaminaoki/anaconda3/lib/python3.6/site-packages/selenium/webdriver/remote/webdriver.py", line 489, in find_element_by_name
    return self.find_element(by=By.NAME, value=name)
  File "/Users/murakaminaoki/anaconda3/lib/python3.6/site-packages/selenium/webdriver/remote/webdriver.py", line 957, in find_element
    'value': value})['value']
  File "/Users/murakaminaoki/anaconda3/lib/python3.6/site-packages/selenium/webdriver/remote/webdriver.py", line 314, in execute
    self.error_handler.check_response(response)
  File "/Users/murakaminaoki/anaconda3/lib/python3.6/site-packages/selenium/webdriver/remote/errorhandler.py", line 242, in check_response
    raise exception_class(message, screen, stacktrace)
selenium.common.exceptions.NoSuchElementException: Message: no such element: Unable to locate element: {"method":"name","selector":"login"}
  (Session info: headless chrome=68.0.3440.106)
  (Driver info: chromedriver=2.40.565386 (45a059dc425e08165f9a10324bd1380cc13ca363),platform=Mac OS X 10.13.6 x86_64)


During handling of the above exception, another exception occurred:

Traceback (most recent call last):
  File "/Users/murakaminaoki/git/atwiki/atwiki.py", line 40, in <module>
    print("\u4f8b\u5916\u304c\u767a\u751f\u3057\u307e\u3057\u305f\uff08\u30cd\u30c3\u30c8\u30ef\u30fc\u30af\u306b\u7e4b\u304c\u3063\u3066\u3044\u308b\u304b\u3054\u78ba\u8a8d\u304f\u3060\u3055\u3044\uff09")
UnicodeEncodeError: 'ascii' codec can't encode characters in position 0-31: ordinal not in range(128)
Traceback (most recent call last):
  File "/Users/murakaminaoki/git/atwiki/atwiki.py", line 34, in <module>
    driver.find_element_by_name("login").click()
  File "/Users/murakaminaoki/anaconda3/lib/python3.6/site-packages/selenium/webdriver/remote/webdriver.py", line 489, in find_element_by_name
    return self.find_element(by=By.NAME, value=name)
  File "/Users/murakaminaoki/anaconda3/lib/python3.6/site-packages/selenium/webdriver/remote/webdriver.py", line 957, in find_element
    'value': value})['value']
  File "/Users/murakaminaoki/anaconda3/lib/python3.6/site-packages/selenium/webdriver/remote/webdriver.py", line 314, in execute
    self.error_handler.check_response(response)
  File "/Users/murakaminaoki/anaconda3/lib/python3.6/site-packages/selenium/webdriver/remote/errorhandler.py", line 242, in check_response
    raise exception_class(message, screen, stacktrace)
selenium.common.exceptions.NoSuchElementException: Message: no such element: Unable to locate element: {"method":"name","selector":"login"}
  (Session info: headless chrome=68.0.3440.106)
  (Driver info: chromedriver=2.40.565386 (45a059dc425e08165f9a10324bd1380cc13ca363),platform=Mac OS X 10.13.6 x86_64)


During handling of the above exception, another exception occurred:

Traceback (most recent call last):
  File "/Users/murakaminaoki/git/atwiki/atwiki.py", line 40, in <module>
    print("\u4f8b\u5916\u304c\u767a\u751f\u3057\u307e\u3057\u305f\uff08\u30cd\u30c3\u30c8\u30ef\u30fc\u30af\u306b\u7e4b\u304c\u3063\u3066\u3044\u308b\u304b\u3054\u78ba\u8a8d\u304f\u3060\u3055\u3044\uff09")
UnicodeEncodeError: 'ascii' codec can't encode characters in position 0-31: ordinal not in range(128)
Traceback (most recent call last):
  File "/Users/murakaminaoki/git/atwiki/atwiki.py", line 34, in <module>
    driver.find_element_by_name("login").click()
  File "/Users/murakaminaoki/anaconda3/lib/python3.6/site-packages/selenium/webdriver/remote/webdriver.py", line 489, in find_element_by_name
    return self.find_element(by=By.NAME, value=name)
  File "/Users/murakaminaoki/anaconda3/lib/python3.6/site-packages/selenium/webdriver/remote/webdriver.py", line 957, in find_element
    'value': value})['value']
  File "/Users/murakaminaoki/anaconda3/lib/python3.6/site-packages/selenium/webdriver/remote/webdriver.py", line 314, in execute
    self.error_handler.check_response(response)
  File "/Users/murakaminaoki/anaconda3/lib/python3.6/site-packages/selenium/webdriver/remote/errorhandler.py", line 242, in check_response
    raise exception_class(message, screen, stacktrace)
selenium.common.exceptions.NoSuchElementException: Message: no such element: Unable to locate element: {"method":"name","selector":"login"}
  (Session info: headless chrome=68.0.3440.106)
  (Driver info: chromedriver=2.40.565386 (45a059dc425e08165f9a10324bd1380cc13ca363),platform=Mac OS X 10.13.6 x86_64)


During handling of the above exception, another exception occurred:

Traceback (most recent call last):
  File "/Users/murakaminaoki/git/atwiki/atwiki.py", line 40, in <module>
    print("\u4f8b\u5916\u304c\u767a\u751f\u3057\u307e\u3057\u305f\uff08\u30cd\u30c3\u30c8\u30ef\u30fc\u30af\u306b\u7e4b\u304c\u3063\u3066\u3044\u308b\u304b\u3054\u78ba\u8a8d\u304f\u3060\u3055\u3044\uff09")
UnicodeEncodeError: 'ascii' codec can't encode characters in position 0-31: ordinal not in range(128)
Traceback (most recent call last):
  File "/Users/murakaminaoki/git/atwiki/atwiki.py", line 34, in <module>
    driver.find_element_by_name("login").click()
  File "/Users/murakaminaoki/anaconda3/lib/python3.6/site-packages/selenium/webdriver/remote/webdriver.py", line 489, in find_element_by_name
    return self.find_element(by=By.NAME, value=name)
  File "/Users/murakaminaoki/anaconda3/lib/python3.6/site-packages/selenium/webdriver/remote/webdriver.py", line 957, in find_element
    'value': value})['value']
  File "/Users/murakaminaoki/anaconda3/lib/python3.6/site-packages/selenium/webdriver/remote/webdriver.py", line 314, in execute
    self.error_handler.check_response(response)
  File "/Users/murakaminaoki/anaconda3/lib/python3.6/site-packages/selenium/webdriver/remote/errorhandler.py", line 242, in check_response
    raise exception_class(message, screen, stacktrace)
selenium.common.exceptions.NoSuchElementException: Message: no such element: Unable to locate element: {"method":"name","selector":"login"}
  (Session info: headless chrome=68.0.3440.106)
  (Driver info: chromedriver=2.40.565386 (45a059dc425e08165f9a10324bd1380cc13ca363),platform=Mac OS X 10.13.6 x86_64)


During handling of the above exception, another exception occurred:

Traceback (most recent call last):
  File "/Users/murakaminaoki/git/atwiki/atwiki.py", line 40, in <module>
    print("\u4f8b\u5916\u304c\u767a\u751f\u3057\u307e\u3057\u305f\uff08\u30cd\u30c3\u30c8\u30ef\u30fc\u30af\u306b\u7e4b\u304c\u3063\u3066\u3044\u308b\u304b\u3054\u78ba\u8a8d\u304f\u3060\u3055\u3044\uff09")
UnicodeEncodeError: 'ascii' codec can't encode characters in position 0-31: ordinal not in range(128)
Traceback (most recent call last):
  File "/Users/murakaminaoki/git/atwiki/atwiki.py", line 34, in <module>
    driver.find_element_by_name("login").click()
  File "/Users/murakaminaoki/anaconda3/lib/python3.6/site-packages/selenium/webdriver/remote/webdriver.py", line 489, in find_element_by_name
    return self.find_element(by=By.NAME, value=name)
  File "/Users/murakaminaoki/anaconda3/lib/python3.6/site-packages/selenium/webdriver/remote/webdriver.py", line 957, in find_element
    'value': value})['value']
  File "/Users/murakaminaoki/anaconda3/lib/python3.6/site-packages/selenium/webdriver/remote/webdriver.py", line 314, in execute
    self.error_handler.check_response(response)
  File "/Users/murakaminaoki/anaconda3/lib/python3.6/site-packages/selenium/webdriver/remote/errorhandler.py", line 242, in check_response
    raise exception_class(message, screen, stacktrace)
selenium.common.exceptions.NoSuchElementException: Message: no such element: Unable to locate element: {"method":"name","selector":"login"}
  (Session info: headless chrome=68.0.3440.106)
  (Driver info: chromedriver=2.40.565386 (45a059dc425e08165f9a10324bd1380cc13ca363),platform=Mac OS X 10.13.6 x86_64)


During handling of the above exception, another exception occurred:

Traceback (most recent call last):
  File "/Users/murakaminaoki/git/atwiki/atwiki.py", line 40, in <module>
    print("\u4f8b\u5916\u304c\u767a\u751f\u3057\u307e\u3057\u305f\uff08\u30cd\u30c3\u30c8\u30ef\u30fc\u30af\u306b\u7e4b\u304c\u3063\u3066\u3044\u308b\u304b\u3054\u78ba\u8a8d\u304f\u3060\u3055\u3044\uff09")
UnicodeEncodeError: 'ascii' codec can't encode characters in position 0-31: ordinal not in range(128)
Traceback (most recent call last):
  File "/Users/murakaminaoki/git/atwiki/atwiki.py", line 34, in <module>
    driver.find_element_by_name("login").click()
  File "/Users/murakaminaoki/anaconda3/lib/python3.6/site-packages/selenium/webdriver/remote/webdriver.py", line 489, in find_element_by_name
    return self.find_element(by=By.NAME, value=name)
  File "/Users/murakaminaoki/anaconda3/lib/python3.6/site-packages/selenium/webdriver/remote/webdriver.py", line 957, in find_element
    'value': value})['value']
  File "/Users/murakaminaoki/anaconda3/lib/python3.6/site-packages/selenium/webdriver/remote/webdriver.py", line 314, in execute
    self.error_handler.check_response(response)
  File "/Users/murakaminaoki/anaconda3/lib/python3.6/site-packages/selenium/webdriver/remote/errorhandler.py", line 242, in check_response
    raise exception_class(message, screen, stacktrace)
selenium.common.exceptions.NoSuchElementException: Message: no such element: Unable to locate element: {"method":"name","selector":"login"}
  (Session info: headless chrome=68.0.3440.106)
  (Driver info: chromedriver=2.40.565386 (45a059dc425e08165f9a10324bd1380cc13ca363),platform=Mac OS X 10.13.6 x86_64)


During handling of the above exception, another exception occurred:

Traceback (most recent call last):
  File "/Users/murakaminaoki/git/atwiki/atwiki.py", line 40, in <module>
    print("\u4f8b\u5916\u304c\u767a\u751f\u3057\u307e\u3057\u305f\uff08\u30cd\u30c3\u30c8\u30ef\u30fc\u30af\u306b\u7e4b\u304c\u3063\u3066\u3044\u308b\u304b\u3054\u78ba\u8a8d\u304f\u3060\u3055\u3044\uff09")
UnicodeEncodeError: 'ascii' codec can't encode characters in position 0-31: ordinal not in range(128)
Traceback (most recent call last):
  File "/Users/murakaminaoki/git/atwiki/atwiki.py", line 34, in <module>
    driver.find_element_by_name("login").click()
  File "/Users/murakaminaoki/anaconda3/lib/python3.6/site-packages/selenium/webdriver/remote/webdriver.py", line 489, in find_element_by_name
    return self.find_element(by=By.NAME, value=name)
  File "/Users/murakaminaoki/anaconda3/lib/python3.6/site-packages/selenium/webdriver/remote/webdriver.py", line 957, in find_element
    'value': value})['value']
  File "/Users/murakaminaoki/anaconda3/lib/python3.6/site-packages/selenium/webdriver/remote/webdriver.py", line 314, in execute
    self.error_handler.check_response(response)
  File "/Users/murakaminaoki/anaconda3/lib/python3.6/site-packages/selenium/webdriver/remote/errorhandler.py", line 242, in check_response
    raise exception_class(message, screen, stacktrace)
selenium.common.exceptions.NoSuchElementException: Message: no such element: Unable to locate element: {"method":"name","selector":"login"}
  (Session info: headless chrome=68.0.3440.106)
  (Driver info: chromedriver=2.40.565386 (45a059dc425e08165f9a10324bd1380cc13ca363),platform=Mac OS X 10.13.6 x86_64)


During handling of the above exception, another exception occurred:

Traceback (most recent call last):
  File "/Users/murakaminaoki/git/atwiki/atwiki.py", line 40, in <module>
    print("\u4f8b\u5916\u304c\u767a\u751f\u3057\u307e\u3057\u305f\uff08\u30cd\u30c3\u30c8\u30ef\u30fc\u30af\u306b\u7e4b\u304c\u3063\u3066\u3044\u308b\u304b\u3054\u78ba\u8a8d\u304f\u3060\u3055\u3044\uff09")
UnicodeEncodeError: 'ascii' codec can't encode characters in position 0-31: ordinal not in range(128)
Traceback (most recent call last):
  File "/Users/murakaminaoki/git/atwiki/atwiki.py", line 34, in <module>
    driver.find_element_by_name("login").click()
  File "/Users/murakaminaoki/anaconda3/lib/python3.6/site-packages/selenium/webdriver/remote/webdriver.py", line 489, in find_element_by_name
    return self.find_element(by=By.NAME, value=name)
  File "/Users/murakaminaoki/anaconda3/lib/python3.6/site-packages/selenium/webdriver/remote/webdriver.py", line 957, in find_element
    'value': value})['value']
  File "/Users/murakaminaoki/anaconda3/lib/python3.6/site-packages/selenium/webdriver/remote/webdriver.py", line 314, in execute
    self.error_handler.check_response(response)
  File "/Users/murakaminaoki/anaconda3/lib/python3.6/site-packages/selenium/webdriver/remote/errorhandler.py", line 242, in check_response
    raise exception_class(message, screen, stacktrace)
selenium.common.exceptions.NoSuchElementException: Message: no such element: Unable to locate element: {"method":"name","selector":"login"}
  (Session info: headless chrome=68.0.3440.106)
  (Driver info: chromedriver=2.40.565386 (45a059dc425e08165f9a10324bd1380cc13ca363),platform=Mac OS X 10.13.6 x86_64)


During handling of the above exception, another exception occurred:

Traceback (most recent call last):
  File "/Users/murakaminaoki/git/atwiki/atwiki.py", line 40, in <module>
    print("\u4f8b\u5916\u304c\u767a\u751f\u3057\u307e\u3057\u305f\uff08\u30cd\u30c3\u30c8\u30ef\u30fc\u30af\u306b\u7e4b\u304c\u3063\u3066\u3044\u308b\u304b\u3054\u78ba\u8a8d\u304f\u3060\u3055\u3044\uff09")
UnicodeEncodeError: 'ascii' codec can't encode characters in position 0-31: ordinal not in range(128)
Traceback (most recent call last):
  File "/Users/murakaminaoki/git/atwiki/atwiki.py", line 34, in <module>
    driver.find_element_by_name("login").click()
  File "/Users/murakaminaoki/anaconda3/lib/python3.6/site-packages/selenium/webdriver/remote/webdriver.py", line 489, in find_element_by_name
    return self.find_element(by=By.NAME, value=name)
  File "/Users/murakaminaoki/anaconda3/lib/python3.6/site-packages/selenium/webdriver/remote/webdriver.py", line 957, in find_element
    'value': value})['value']
  File "/Users/murakaminaoki/anaconda3/lib/python3.6/site-packages/selenium/webdriver/remote/webdriver.py", line 314, in execute
    self.error_handler.check_response(response)
  File "/Users/murakaminaoki/anaconda3/lib/python3.6/site-packages/selenium/webdriver/remote/errorhandler.py", line 242, in check_response
    raise exception_class(message, screen, stacktrace)
selenium.common.exceptions.NoSuchElementException: Message: no such element: Unable to locate element: {"method":"name","selector":"login"}
  (Session info: headless chrome=68.0.3440.106)
  (Driver info: chromedriver=2.40.565386 (45a059dc425e08165f9a10324bd1380cc13ca363),platform=Mac OS X 10.13.6 x86_64)


During handling of the above exception, another exception occurred:

Traceback (most recent call last):
  File "/Users/murakaminaoki/git/atwiki/atwiki.py", line 40, in <module>
    print("\u4f8b\u5916\u304c\u767a\u751f\u3057\u307e\u3057\u305f\uff08\u30cd\u30c3\u30c8\u30ef\u30fc\u30af\u306b\u7e4b\u304c\u3063\u3066\u3044\u308b\u304b\u3054\u78ba\u8a8d\u304f\u3060\u3055\u3044\uff09")
UnicodeEncodeError: 'ascii' codec can't encode characters in position 0-31: ordinal not in range(128)
Traceback (most recent call last):
  File "/Users/murakaminaoki/git/atwiki/atwiki.py", line 34, in <module>
    driver.find_element_by_name("login").click()
  File "/Users/murakaminaoki/anaconda3/lib/python3.6/site-packages/selenium/webdriver/remote/webdriver.py", line 489, in find_element_by_name
    return self.find_element(by=By.NAME, value=name)
  File "/Users/murakaminaoki/anaconda3/lib/python3.6/site-packages/selenium/webdriver/remote/webdriver.py", line 957, in find_element
    'value': value})['value']
  File "/Users/murakaminaoki/anaconda3/lib/python3.6/site-packages/selenium/webdriver/remote/webdriver.py", line 314, in execute
    self.error_handler.check_response(response)
  File "/Users/murakaminaoki/anaconda3/lib/python3.6/site-packages/selenium/webdriver/remote/errorhandler.py", line 242, in check_response
    raise exception_class(message, screen, stacktrace)
selenium.common.exceptions.NoSuchElementException: Message: no such element: Unable to locate element: {"method":"name","selector":"login"}
  (Session info: headless chrome=68.0.3440.106)
  (Driver info: chromedriver=2.40.565386 (45a059dc425e08165f9a10324bd1380cc13ca363),platform=Mac OS X 10.13.6 x86_64)


During handling of the above exception, another exception occurred:

Traceback (most recent call last):
  File "/Users/murakaminaoki/git/atwiki/atwiki.py", line 40, in <module>
    print("\u4f8b\u5916\u304c\u767a\u751f\u3057\u307e\u3057\u305f\uff08\u30cd\u30c3\u30c8\u30ef\u30fc\u30af\u306b\u7e4b\u304c\u3063\u3066\u3044\u308b\u304b\u3054\u78ba\u8a8d\u304f\u3060\u3055\u3044\uff09")
UnicodeEncodeError: 'ascii' codec can't encode characters in position 0-31: ordinal not in range(128)
Traceback (most recent call last):
  File "/Users/murakaminaoki/git/atwiki/atwiki.py", line 34, in <module>
    driver.find_element_by_name("login").click()
  File "/Users/murakaminaoki/anaconda3/lib/python3.6/site-packages/selenium/webdriver/remote/webdriver.py", line 489, in find_element_by_name
    return self.find_element(by=By.NAME, value=name)
  File "/Users/murakaminaoki/anaconda3/lib/python3.6/site-packages/selenium/webdriver/remote/webdriver.py", line 957, in find_element
    'value': value})['value']
  File "/Users/murakaminaoki/anaconda3/lib/python3.6/site-packages/selenium/webdriver/remote/webdriver.py", line 314, in execute
    self.error_handler.check_response(response)
  File "/Users/murakaminaoki/anaconda3/lib/python3.6/site-packages/selenium/webdriver/remote/errorhandler.py", line 242, in check_response
    raise exception_class(message, screen, stacktrace)
selenium.common.exceptions.NoSuchElementException: Message: no such element: Unable to locate element: {"method":"name","selector":"login"}
  (Session info: headless chrome=68.0.3440.106)
  (Driver info: chromedriver=2.40.565386 (45a059dc425e08165f9a10324bd1380cc13ca363),platform=Mac OS X 10.13.6 x86_64)


During handling of the above exception, another exception occurred:

Traceback (most recent call last):
  File "/Users/murakaminaoki/git/atwiki/atwiki.py", line 40, in <module>
    print("\u4f8b\u5916\u304c\u767a\u751f\u3057\u307e\u3057\u305f\uff08\u30cd\u30c3\u30c8\u30ef\u30fc\u30af\u306b\u7e4b\u304c\u3063\u3066\u3044\u308b\u304b\u3054\u78ba\u8a8d\u304f\u3060\u3055\u3044\uff09")
UnicodeEncodeError: 'ascii' codec can't encode characters in position 0-31: ordinal not in range(128)
Traceback (most recent call last):
  File "/Users/murakaminaoki/git/atwiki/atwiki.py", line 34, in <module>
    driver.find_element_by_name("login").click()
  File "/Users/murakaminaoki/anaconda3/lib/python3.6/site-packages/selenium/webdriver/remote/webdriver.py", line 489, in find_element_by_name
    return self.find_element(by=By.NAME, value=name)
  File "/Users/murakaminaoki/anaconda3/lib/python3.6/site-packages/selenium/webdriver/remote/webdriver.py", line 957, in find_element
    'value': value})['value']
  File "/Users/murakaminaoki/anaconda3/lib/python3.6/site-packages/selenium/webdriver/remote/webdriver.py", line 314, in execute
    self.error_handler.check_response(response)
  File "/Users/murakaminaoki/anaconda3/lib/python3.6/site-packages/selenium/webdriver/remote/errorhandler.py", line 242, in check_response
    raise exception_class(message, screen, stacktrace)
selenium.common.exceptions.NoSuchElementException: Message: no such element: Unable to locate element: {"method":"name","selector":"login"}
  (Session info: headless chrome=68.0.3440.106)
  (Driver info: chromedriver=2.40.565386 (45a059dc425e08165f9a10324bd1380cc13ca363),platform=Mac OS X 10.13.6 x86_64)


During handling of the above exception, another exception occurred:

Traceback (most recent call last):
  File "/Users/murakaminaoki/git/atwiki/atwiki.py", line 40, in <module>
    print("\u4f8b\u5916\u304c\u767a\u751f\u3057\u307e\u3057\u305f\uff08\u30cd\u30c3\u30c8\u30ef\u30fc\u30af\u306b\u7e4b\u304c\u3063\u3066\u3044\u308b\u304b\u3054\u78ba\u8a8d\u304f\u3060\u3055\u3044\uff09")
UnicodeEncodeError: 'ascii' codec can't encode characters in position 0-31: ordinal not in range(128)
Traceback (most recent call last):
  File "/Users/murakaminaoki/git/atwiki/atwiki.py", line 31, in <module>
    driver.find_element_by_link_text("\u30ed\u30b0\u30a4\u30f3").click()
  File "/Users/murakaminaoki/anaconda3/lib/python3.6/site-packages/selenium/webdriver/remote/webdriver.py", line 421, in find_element_by_link_text
    return self.find_element(by=By.LINK_TEXT, value=link_text)
  File "/Users/murakaminaoki/anaconda3/lib/python3.6/site-packages/selenium/webdriver/remote/webdriver.py", line 957, in find_element
    'value': value})['value']
  File "/Users/murakaminaoki/anaconda3/lib/python3.6/site-packages/selenium/webdriver/remote/webdriver.py", line 314, in execute
    self.error_handler.check_response(response)
  File "/Users/murakaminaoki/anaconda3/lib/python3.6/site-packages/selenium/webdriver/remote/errorhandler.py", line 242, in check_response
    raise exception_class(message, screen, stacktrace)
selenium.common.exceptions.NoSuchElementException: Message: no such element: Unable to locate element: {"method":"link text","selector":"\u30ed\u30b0\u30a4\u30f3"}
  (Session info: headless chrome=68.0.3440.106)
  (Driver info: chromedriver=2.40.565386 (45a059dc425e08165f9a10324bd1380cc13ca363),platform=Mac OS X 10.13.6 x86_64)


During handling of the above exception, another exception occurred:

Traceback (most recent call last):
  File "/Users/murakaminaoki/git/atwiki/atwiki.py", line 40, in <module>
    print("\u4f8b\u5916\u304c\u767a\u751f\u3057\u307e\u3057\u305f\uff08\u30cd\u30c3\u30c8\u30ef\u30fc\u30af\u306b\u7e4b\u304c\u3063\u3066\u3044\u308b\u304b\u3054\u78ba\u8a8d\u304f\u3060\u3055\u3044\uff09")
UnicodeEncodeError: 'ascii' codec can't encode characters in position 0-31: ordinal not in range(128)
Traceback (most recent call last):
  File "/Users/murakaminaoki/git/atwiki/atwiki.py", line 34, in <module>
    driver.find_element_by_name("login").click()
  File "/Users/murakaminaoki/anaconda3/lib/python3.6/site-packages/selenium/webdriver/remote/webdriver.py", line 489, in find_element_by_name
    return self.find_element(by=By.NAME, value=name)
  File "/Users/murakaminaoki/anaconda3/lib/python3.6/site-packages/selenium/webdriver/remote/webdriver.py", line 957, in find_element
    'value': value})['value']
  File "/Users/murakaminaoki/anaconda3/lib/python3.6/site-packages/selenium/webdriver/remote/webdriver.py", line 314, in execute
    self.error_handler.check_response(response)
  File "/Users/murakaminaoki/anaconda3/lib/python3.6/site-packages/selenium/webdriver/remote/errorhandler.py", line 242, in check_response
    raise exception_class(message, screen, stacktrace)
selenium.common.exceptions.NoSuchElementException: Message: no such element: Unable to locate element: {"method":"name","selector":"login"}
  (Session info: headless chrome=68.0.3440.106)
  (Driver info: chromedriver=2.40.565386 (45a059dc425e08165f9a10324bd1380cc13ca363),platform=Mac OS X 10.13.6 x86_64)


During handling of the above exception, another exception occurred:

Traceback (most recent call last):
  File "/Users/murakaminaoki/git/atwiki/atwiki.py", line 40, in <module>
    print("\u4f8b\u5916\u304c\u767a\u751f\u3057\u307e\u3057\u305f\uff08\u30cd\u30c3\u30c8\u30ef\u30fc\u30af\u306b\u7e4b\u304c\u3063\u3066\u3044\u308b\u304b\u3054\u78ba\u8a8d\u304f\u3060\u3055\u3044\uff09")
UnicodeEncodeError: 'ascii' codec can't encode characters in position 0-31: ordinal not in range(128)
Traceback (most recent call last):
  File "/Users/murakaminaoki/git/atwiki/atwiki.py", line 34, in <module>
    driver.find_element_by_name("login").click()
  File "/Users/murakaminaoki/anaconda3/lib/python3.6/site-packages/selenium/webdriver/remote/webdriver.py", line 489, in find_element_by_name
    return self.find_element(by=By.NAME, value=name)
  File "/Users/murakaminaoki/anaconda3/lib/python3.6/site-packages/selenium/webdriver/remote/webdriver.py", line 957, in find_element
    'value': value})['value']
  File "/Users/murakaminaoki/anaconda3/lib/python3.6/site-packages/selenium/webdriver/remote/webdriver.py", line 314, in execute
    self.error_handler.check_response(response)
  File "/Users/murakaminaoki/anaconda3/lib/python3.6/site-packages/selenium/webdriver/remote/errorhandler.py", line 242, in check_response
    raise exception_class(message, screen, stacktrace)
selenium.common.exceptions.NoSuchElementException: Message: no such element: Unable to locate element: {"method":"name","selector":"login"}
  (Session info: headless chrome=68.0.3440.106)
  (Driver info: chromedriver=2.40.565386 (45a059dc425e08165f9a10324bd1380cc13ca363),platform=Mac OS X 10.13.6 x86_64)


During handling of the above exception, another exception occurred:

Traceback (most recent call last):
  File "/Users/murakaminaoki/git/atwiki/atwiki.py", line 40, in <module>
    print("\u4f8b\u5916\u304c\u767a\u751f\u3057\u307e\u3057\u305f\uff08\u30cd\u30c3\u30c8\u30ef\u30fc\u30af\u306b\u7e4b\u304c\u3063\u3066\u3044\u308b\u304b\u3054\u78ba\u8a8d\u304f\u3060\u3055\u3044\uff09")
UnicodeEncodeError: 'ascii' codec can't encode characters in position 0-31: ordinal not in range(128)
Traceback (most recent call last):
  File "/Users/murakaminaoki/git/atwiki/atwiki.py", line 34, in <module>
    driver.find_element_by_name("login").click()
  File "/Users/murakaminaoki/anaconda3/lib/python3.6/site-packages/selenium/webdriver/remote/webdriver.py", line 489, in find_element_by_name
    return self.find_element(by=By.NAME, value=name)
  File "/Users/murakaminaoki/anaconda3/lib/python3.6/site-packages/selenium/webdriver/remote/webdriver.py", line 957, in find_element
    'value': value})['value']
  File "/Users/murakaminaoki/anaconda3/lib/python3.6/site-packages/selenium/webdriver/remote/webdriver.py", line 314, in execute
    self.error_handler.check_response(response)
  File "/Users/murakaminaoki/anaconda3/lib/python3.6/site-packages/selenium/webdriver/remote/errorhandler.py", line 242, in check_response
    raise exception_class(message, screen, stacktrace)
selenium.common.exceptions.NoSuchElementException: Message: no such element: Unable to locate element: {"method":"name","selector":"login"}
  (Session info: headless chrome=68.0.3440.106)
  (Driver info: chromedriver=2.40.565386 (45a059dc425e08165f9a10324bd1380cc13ca363),platform=Mac OS X 10.13.6 x86_64)


During handling of the above exception, another exception occurred:

Traceback (most recent call last):
  File "/Users/murakaminaoki/git/atwiki/atwiki.py", line 40, in <module>
    print("\u4f8b\u5916\u304c\u767a\u751f\u3057\u307e\u3057\u305f\uff08\u30cd\u30c3\u30c8\u30ef\u30fc\u30af\u306b\u7e4b\u304c\u3063\u3066\u3044\u308b\u304b\u3054\u78ba\u8a8d\u304f\u3060\u3055\u3044\uff09")
UnicodeEncodeError: 'ascii' codec can't encode characters in position 0-31: ordinal not in range(128)
